Workbook
Name WoS: Dienste!$L$2:$L$20
Name SoS: Dienste!$J$2:$J$20
Name WmS: Dienste!$K$2:$K$29
Name SmS: Dienste!$I$2:$I$29

Sheet Lenkerstunden
A1: Lenkerstunden
A2: Monat | E2: MoFroS | F2: =175/24 -> 7.2916667 | G2: =251.08/24 -> 10.461667
A3: Jahr | E3: Samstag | F3: =35/24 -> 1.4583333
A4: Gesamtstunden | E4: So. u. Fe. | F4: 0
E5: Gesamt | F5: =SUM(F2:F3) -> 8.75
E6: Dienst-Nr. | F6: 2202 | G6: 2203 | H6: 2204 | I6: 2205 | J6: 2206 | K6: 2207 | L6: 2301 | M6: 2302 | N6: 2303 | O6: 2304 | P6: 2501 | Q6: 2502 | R6: 2503 | S6: 2504 | T6: 2601 | U6: 2602 | V6: 2801 | W6: 2802 | X6: 2201 | Y6: 2803 | Z6: 2804 | AA6: 2805 | AB6: 280X
A7: Lenker | B7: Soll-Std. | C7: Ist-Std. | D7: Abw. [%] | E7: Anz. [So.]
A8: Andreas Brugger | B8: =VLOOKUP(A8,Lenker!$A$2:$B$22,2,FALSE) -> #N/A
A10: Arnold Pali | B10: =VLOOKUP(A10,Lenker!$A$2:$B$22,2,FALSE) -> #N/A
A12: Daniel Gruber | B12: =VLOOKUP(A12,Lenker!$A$2:$B$22,2,FALSE) -> #N/A
A14: Darko Peric | B14: =VLOOKUP(A14,Lenker!$A$2:$B$22,2,FALSE) -> #N/A
A16: Dean Todic | B16: =VLOOKUP(A16,Lenker!$A$2:$B$22,2,FALSE) -> #N/A
A18: Gernot Mitterbäck | B18: =VLOOKUP(A18,Lenker!$A$2:$B$22,2,FALSE) -> #N/A
A20: Goran Rasic | B20: =VLOOKUP(A20,Lenker!$A$2:$B$22,2,FALSE) -> #N/A
A22: Hannes Gigler | B22: =VLOOKUP(A22,Lenker!$A$2:$B$22,2,FALSE) -> #N/A
A24: Hannes Koch | B24: =VLOOKUP(A24,Lenker!$A$2:$B$22,2,FALSE) -> #N/A
A26: Herwig Platzner | B26: =VLOOKUP(A26,Lenker!$A$2:$B$22,2,FALSE) -> #N/A
A28: Iosif Bagosi | B28: =VLOOKUP(A28,Lenker!$A$2:$B$22,2,FALSE) -> #N/A
A30: Zoltan Molnar | B30: =VLOOKUP(A30,Lenker!$A$2:$B$22,2,FALSE) -> #N/A
... A84: Manfred Striedinger | B84: =VLOOKUP(A84,Lenker!$A$2:$B$22,2,FALSE) -> #N/A

Sheet Dienste
A1: Linien / Dienst | B1: Dienst-Nr. | C1: VAD [mS] | D1: VAD [oS] | E1: Diäten | F1: Tag | G1: KFZ-Ort | I1: SmS | J1: SoS | K1: WmS | L1: WoS
A2: Dienst 1 | B2: 401mS | C2: 0.45347222 | D2: 0 | E2: 11 | F2: Mo-Fr | G2: Leiten | I2: 401mS | J2: 431oS | K2: 401mS WI | L2: 431oS WI
A3: Dienst 2 | B3: 401mS WI | C3: 0.47152778 | D3: 0 | E3: 11 | F3: Mo-Fr | G3: Oberglan | I3: 402mS | J3: 432oS | K3: 402mS | L3: 432oS
A4: Dienst 3 | B4: 402mS | C4: 0.44652778 | D4: 0 | E4: 11 | F4: Mo-Fr | G4: Deutsch Griffen | I4: 403mS | J4: 433oS | K4: 403mS | L4: 433oS
A5: Dienst 4 | B5: 403mS | C5: 0.45277778 | D5: 0 | E5: 11 | F5: Mo-Fr | G5: Himmelberg | I5: 404mS | J5: 434oS | K5: 404mS | L5: 434oS
A6: Dienst 5 | B6: 404mS | C6: 0.50416667 | D6: 0 | E6: 12 | F6: Mo-Fr | G6: Sirnitz | I6: 405mS | J6: 435oS-HOF | K6: 405mS | L6: 435oS-HOF
A7: Dienst 6 | B7: 405mS | C7: 0.43125 | D7: 0 | E7: 10 | F7: Mo-Fr | G7: Ossiach | I7: 406mS | J7: 436oS-TAF | K7: 406mS | L7: 436oS-TAF
A8: Dienst 7 | B8: 406mS | C8: 0.45416667 | D8: 0 | E8: 11 | F8: Mo-Fr | G8: Oberglan | I8: 407mS | J8: 437oS | K8: 407mS | L8: 437oS
A9: Dienst 8 | B9: 407mS | C9: 0.45347222 | D9: 0 | E9: 11 | F9: Mo-Fr | G9: Deutsch Griffen | I9: 408mS-HOF | J9: 438oS | K9: 408mS-HOF | L9: 438oS
A10: Dienst 9 | B10: 408mS-HOF | C10: 0.48402778 | D10: 0 | E10: 12 | F10: Mo-Fr | G10: Zammelsberg | I10: 409mS | J10: 439oS | K10: 409mS | L10: 439oS
A11: Dienst 10 | B11: 409mS | C11: 0.40416667 | D11: 0 | E11: 10 | F11: Mo-Fr | G11: Oberglan | I11: 410mS-TAF | J11: 440oS | K11: 410mS-TAF | L11: 440oS
A12: Dienst 11 | B12: 410mS-TAF | C12: 0.44930556 | D12: 0 | E12: 11 | F12: Mo-Fr | G12: Predlkreuz | I12: 411mS | J12: 451SA | K12: 411mS | L12: 451SA
A13: Dienst 12 | B13: 411mS | C13: 0.49652778 | D13: 0 | E13: 12 | F13: Mo-Fr | G13: Reichenau | I13: 412mS | J13: 452SA | K13: 412mS | L13: 452SA
... A20: Dienst 19 | B20: 416mS-WER | C20: 0.125 | D20: 0 | E20: 3 | F20: Mo-Fr | G20: Feldkirchen | I20: 417mS-WER | J20: DI | K20: 417mS-WER | L20: DI
A21: Dienst 20 | B21: 417mS-WER | C21: 0.125 | D21: 0 | E21: 3 | F21: Mo-Fr | G21: Feldkirchen | I21: 451SA | K21: 451SA
A22: Dienst 21 | B22: 431oS | C22: 0.45347222 | D22: 0.45347222 | E22: 11 | F22: Mo-Fr | G22: Leiten | I22: 452SA | K22: 452SA
A23: Dienst 22 | B23: 431oS WI | C23: 0.47152778 | D23: 0.47152778 | E23: 11 | F23: Mo-Fr | G23: Oberglan | I23: FT | K23: FT
A24: Dienst 23 | B24: 432oS | C24: 0.49513889 | D24: 0.49513889 | E24: 12 | F24: Mo-Fr | G24: Deutsch Griffen | I24: K | K24: K
A25: Dienst 24 | B25: 433oS | C25: 0.47916667 | D25: 0.47916667 | E25: 11 | F25: Mo-Fr | G25: Himmelberg | I25: F | K25: F
A26: Dienst 25 | B26: 434oS | C26: 0.43125 | D26: 0.43125 | E26: 10 | F26: Mo-Fr | G26: Ossiach | I26: U | K26: U
A27: Dienst 26 | B27: 435oS-HOF | C27: 0.48402778 | D27: 0.48402778 | E27: 12 | F27: Mo-Fr | G27: Zammelsberg | I27: SOF | K27: SOF
A28: Dienst 27 | B28: 436oS-TAF | C28: 0.42152778 | D28: 0.42152778 | E28: 10 | F28: Mo-Fr | G28: Predlkreuz | I28: MB | K28: MB
A29: Dienst 28 | B29: 437oS | C29: 0.42638889 | D29: 0.42638889 | E29: 11 | F29: Mo-Fr | G29: Oberglan | I29: DI | K29: DI
A30: Dienst 29 | B30: 438oS | C30: 0.46388889 | D30: 0.46388889 | E30: 11 | F30: Mo-Fr | G30: Oberglan
A31: Dienst 30 | B31: 439oS | C31: 0.51944444 | D31: 0.51944444 | E31: 12 | F31: Mo-Fr | G31: Reichenau
A32: Dienst 31 | B32: 440oS | C32: 0.125 | D32: 0.125 | E32: 3 | F32: Mo-Fr | G32: Klagenfurt
A33: Dienst 32 | B33: 451SA | C33: 0.39652778 | D33: 0 | E33: 10 | F33: Sa. | G33: Reichenau
A34: Dienst 33 | B34: 452SA | C34: 0.40416667 | D34: 0 | E34: 10 | F34: Sa. | G34: Deutsch Griffen
A35: Feiertag | B35: FT | C35: 0.29166667 | D35: 0 | E35: 0 | F35: - | G35: -
A36: Krank | B36: K | C36: 0.33333333 | D36: 0 | E36: 0 | F36: - | G36: -
A37: FREI | B37: F | C37: 0 | D37: 0 | E37: 0 | F37: - | G37: -
A38: Urlaub | B38: U | C38: 0.375 | D38: 0 | E38: 0 | F38: - | G38: -
A39: Sonderfahrt | B39: SOF | D39: 0 | E39: 0 | F39: - | G39: -
A40: Mobilbüro | B40: MB | C40: 0.1875 | D40: 0 | E40: 0
A41: Dispo | B41: DI | C41: 0.375 | D41: 0 | E41: 9 | F41: Mo-Fr | G41: -

Sheet Lenker
A1: Lenker | B1: Soll-Std. | C1: B-Grad [%] | D1: Feiertag | E1: Urlaub | F1: Krankenstand | G1: Fixdienst m.S. | H1: Fixdienst o.S.
A2: Blaskovic, Nenad | B2: 7.25 | C2: =Lenker!$B2/$B$24 -> 1.0046189 | D2: =$B$25*Lenker!$C2 -> 0.29301386 | E2: 0 | F2: =$B$26*Lenker!$C2 -> 0.33487298 | G2: 409 | H2: frei
A3: Fröhlacher, Hubert | B3: 6.4583333 | C3: =Lenker!$B3/$B$24 -> 0.89491917 | D3: =$B$25*Lenker!$C3 -> 0.26101809 | E3: 0 | F3: =$B$26*Lenker!$C3 -> 0.29830639 | G3: 411 + 412
A4: Genäuß, Thomas | B4: 7.25 | C4: =Lenker!$B4/$B$24 -> 1.0046189 | D4: =$B$25*Lenker!$C4 -> 0.29301386 | E4: 0 | F4: =$B$26*Lenker!$C4 -> 0.33487298
A5: Hinteregger, Manfred | B5: 7.25 | C5: =Lenker!$B5/$B$24 -> 1.0046189 | D5: =$B$25*Lenker!$C5 -> 0.29301386 | E5: 0 | F5: =$B$26*Lenker!$C5 -> 0.33487298 | G5: 401 | H5: 431
A6: Kandolf, Alfred | B6: 7.25 | C6: =Lenker!$B6/$B$24 -> 1.0046189 | D6: =$B$25*Lenker!$C6 -> 0.29301386 | E6: 0 | F6: =$B$26*Lenker!$C6 -> 0.33487298 | G6: 405 | H6: 434
A7: Konheiser, Elisabeth | B7: 7.25 | C7: =Lenker!$B7/$B$24 -> 1.0046189 | D7: =$B$25*Lenker!$C7 -> 0.29301386 | E7: 0 | F7: =$B$26*Lenker!$C7 -> 0.33487298 | G7: 414 | H7: MB
A8: Lauhart, Egon | B8: 7.25 | C8: =Lenker!$B8/$B$24 -> 1.0046189 | D8: =$B$25*Lenker!$C8 -> 0.29301386 | E8: 0 | F8: =$B$26*Lenker!$C8 -> 0.33487298
A9: Madrutter, Anton | B9: 7.25 | C9: =Lenker!$B9/$B$24 -> 1.0046189 | D9: =$B$25*Lenker!$C9 -> 0.29301386 | E9: 0 | F9: =$B$26*Lenker!$C9 -> 0.33487298 | G9: 412 + 411 | H9: 439
A10: Niederbichler, Daniel | B10: 7.25 | C10: =Lenker!$B10/$B$24 -> 1.0046189 | D10: =$B$25*Lenker!$C10 -> 0.29301386 | E10: 0 | F10: =$B$26*Lenker!$C10 -> 0.33487298 | G10: 403 | H10: 433
A11: Nurikic, Ervin | B11: 7.25 | C11: =Lenker!$B11/$B$24 -> 1.0046189 | D11: =$B$25*Lenker!$C11 -> 0.29301386 | E11: 0 | F11: =$B$26*Lenker!$C11 -> 0.33487298 | G11: DI | H11: DI
A12: Obersteiner, Roland | B12: 7.25 | C12: =Lenker!$B12/$B$24 -> 1.0046189 | D12: =$B$25*Lenker!$C12 -> 0.29301386 | E12: 0 | F12: =$B$26*Lenker!$C12 -> 0.33487298 | G12: 404
A13: Rauter, Agnes Zita | B13: 7.25 | C13: =Lenker!$B13/$B$24 -> 1.0046189 | D13: =$B$25*Lenker!$C13 -> 0.29301386 | E13: 0 | F13: =$B$26*Lenker!$C13 -> 0.33487298 | G13: 402 | H13: 432
A14: Simon, Otto | B14: 7.25 | C14: =Lenker!$B14/$B$24 -> 1.0046189 | D14: =$B$25*Lenker!$C14 -> 0.29301386 | E14: 0 | F14: =$B$26*Lenker!$C14 -> 0.33487298 | G14: 413 | H14: 437
A15: Bandzi, Attila | B15: 7.25 | C15: =Lenker!$B15/$B$24 -> 1.0046189 | D15: =$B$25*Lenker!$C15 -> 0.29301386 | E15: 0 | F15: =$B$26*Lenker!$C15 -> 0.33487298 | G15: 407 | H15: 438
A16: Struckl, Stefan | B16: 7.25 | C16: =Lenker!$B16/$B$24 -> 1.0046189 | D16: =$B$25*Lenker!$C16 -> 0.29301386 | E16: 0 | F16: =$B$26*Lenker!$C16 -> 0.33487298 | G16: 406 | H16: 438
A17: Merz, Matthias | B17: 1.6666667 | C17: =Lenker!$B17/$B$24 -> 0.23094688 | D17: =$B$25*Lenker!$C17 -> 0.067359507 | E17: 0 | F17: =$B$26*Lenker!$C17 -> 0.076982294
A18: Granitzer, Hermann | B18: 1.6666667 | C18: =Lenker!$B18/$B$24 -> 0.23094688 | D18: =$B$25*Lenker!$C18 -> 0.067359507 | E18: 0 | F18: =$B$26*Lenker!$C18 -> 0.076982294
A19: Thamer, Karl | B19: 7.25 | C19: =Lenker!$B19/$B$24 -> 1.0046189 | D19: =$B$25*Lenker!$C19 -> 0.29301386 | E19: 0 | F19: =$B$26*Lenker!$C19 -> 0.33487298 | G19: 411 + 412 | H19: 439
A20: Sulics, Egon | B20: 4.1666667 | C20: =Lenker!$B20/$B$24 -> 0.57736721 | D20: =$B$25*Lenker!$C20 -> 0.16839877 | E20: 0 | F20: =$B$26*Lenker!$C20 -> 0.19245574
A21: Klagenfurt - Fahrer | B21: 2.75 | C21: =Lenker!$B21/$B$24 -> 0.38106236 | D21: =$B$25*Lenker!$C21 -> 0.11114319 | E21: 0 | F21: =$B$26*Lenker!$C21 -> 0.12702079 | G21: 415 | H21: 415
A22: Klagenfurt - Samstagsfahrer | B22: 1.6666667 | C22: =Lenker!$B22/$B$24 -> 0.23094688 | D22: =$B$25*Lenker!$C22 -> 0.067359507 | E22: 0 | F22: =$B$26*Lenker!$C22 -> 0.076982294 | G22: 452 | H22: 452
C23: Summe | D23: =SUBTOTAL(109,Lenker!$D$2:$D$22) -> 5.1378464
A24: Vollzeitbeschäftigung: | B24: 7.2166667
A25: Feiertagsvergütung [Vollzeit]: | B25: 0.29166667
A26: Krankenstand [Vollzeit]: | B26: 0.33333333

Sheet Feiertage
A1: Feiertag | B1: Datum
A2: Neujahr | B2: 45658
A3: Heilige Drei Könige | B3: 45663
A4: Ostermontag | B4: 45768
A5: Staatsfeiertag | B5: 45778
A6: Christi Himmelfahrt | B6: 45806
A7: Pfingstmontag | B7: 45817
A8: Fronleichnam | B8: 45827
A9: Mariä Himmelfahrt | B9: 45884
A10: Nationalfeiertag | B10: 45956
A11: Allerheiligen | B11: 45962
A12: Mariä Empfängnis | B12: 45999
A13: Weihnachten | B13: 46016
A14: Stefanitag | B14: 46017

Sheet DP-Vorlage
A1: Dienstplan - Feldkirchen | E1: Sollstd. [mS] | F1: Sollstd. [oS] | H1: =IF(OR(H5=Feiertage!$B$2,H5=Feiertage!$B$3,H5=Feiertage!$B$4,H5=Feiertage!$B$5,H5=Feiertage!$B$6,H5=Feiertage!$B$7,H5=Feiertage!$B$8,H5=Feiertage!$B$9,H5=Feiertage!$B$10,H5=Feiertage!$B$11,H5=Feiertage!$B$12,H5=Feiertage!$B$13,H5=Feiertage!$B$14),"Feiertag","-") -> - | L1: =IF(OR(L5=Feiertage!$B$2,L5=Feiertage!$B$3,L5=Feiertage!$B$4,L5=Feiertage!$B$5,L5=Feiertage!$B$6,L5=Feiertage!$B$7,L5=Feiertage!$B$8,L5=Feiertage!$B$9,L5=Feiertage!$B$10,L5=Feiertage!$B$11,L5=Feiertage!$B$12,L5=Feiertage!$B$13,L5=Feiertage!$B$14),"Feiertag","-") -> - | P1: =IF(OR(P5=Feiertage!$B$2,P5=Feiertage!$B$3,P5=Feiertage!$B$4,P5=Feiertage!$B$5,P5=Feiertage!$B$6,P5=Feiertage!$B$7,P5=Feiertage!$B$8,P5=Feiertage!$B$9,P5=Feiertage!$B$10,P5=Feiertage!$B$11,P5=Feiertage!$B$12,P5=Feiertage!$B$13,P5=Feiertage!$B$14),"Feiertag","-") -> - | T1: =IF(OR(T5=Feiertage!$B$2,T5=Feiertage!$B$3,T5=Feiertage!$B$4,T5=Feiertage!$B$5,T5=Feiertage!$B$6,T5=Feiertage!$B$7,T5=Feiertage!$B$8,T5=Feiertage!$B$9,T5=Feiertage!$B$10,T5=Feiertage!$B$11,T5=Feiertage!$B$12,T5=Feiertage!$B$13,T5=Feiertage!$B$14),"Feiertag","-") -> - | X1: =IF(OR(X5=Feiertage!$B$2,X5=Feiertage!$B$3,X5=Feiertage!$B$4,X5=Feiertage!$B$5,X5=Feiertage!$B$6,X5=Feiertage!$B$7,X5=Feiertage!$B$8,X5=Feiertage!$B$9,X5=Feiertage!$B$10,X5=Feiertage!$B$11,X5=Feiertage!$B$12,X5=Feiertage!$B$13,X5=Feiertage!$B$14),"Feiertag","-") -> - | AB1: =IF(OR(AB5=Feiertage!$B$2,AB5=Feiertage!$B$3,AB5=Feiertage!$B$4,AB5=Feiertage!$B$5,AB5=Feiertage!$B$6,AB5=Feiertage!$B$7,AB5=Feiertage!$B$8,AB5=Feiertage!$B$9,AB5=Feiertage!$B$10,AB5=Feiertage!$B$11,AB5=Feiertage!$B$12,AB5=Feiertage!$B$13,AB5=Feiertage!$B$14),"Feiertag","-") -> - | AF1: =IF(OR(AF5=Feiertage!$B$2,AF5=Feiertage!$B$3,AF5=Feiertage!$B$4,AF5=Feiertage!$B$5,AF5=Feiertage!$B$6,AF5=Feiertage!$B$7,AF5=Feiertage!$B$8,AF5=Feiertage!$B$9,AF5=Feiertage!$B$10,AF5=Feiertage!$B$11,AF5=Feiertage!$B$12,AF5=Feiertage!$B$13,AF5=Feiertage!$B$14),"Feiertag","-") -> - | AJ1: =IF(OR(AJ5=Feiertage!$B$2,AJ5=Feiertage!$B$3,AJ5=Feiertage!$B$4,AJ5=Feiertage!$B$5,AJ5=Feiertage!$B$6,AJ5=Feiertage!$B$7,AJ5=Feiertage!$B$8,AJ5=Feiertage!$B$9,AJ5=Feiertage!$B$10,AJ5=Feiertage!$B$11,AJ5=Feiertage!$B$12,AJ5=Feiertage!$B$13,AJ5=Feiertage!$B$14),"Feiertag","-") -> - | AN1: =IF(OR(AN5=Feiertage!$B$2,AN5=Feiertage!$B$3,AN5=Feiertage!$B$4,AN5=Feiertage!$B$5,AN5=Feiertage!$B$6,AN5=Feiertage!$B$7,AN5=Feiertage!$B$8,AN5=Feiertage!$B$9,AN5=Feiertage!$B$10,AN5=Feiertage!$B$11,AN5=Feiertage!$B$12,AN5=Feiertage!$B$13,AN5=Feiertage!$B$14),"Feiertag","-") -> - | AR1: =IF(OR(AR5=Feiertage!$B$2,AR5=Feiertage!$B$3,AR5=Feiertage!$B$4,AR5=Feiertage!$B$5,AR5=Feiertage!$B$6,AR5=Feiertage!$B$7,AR5=Feiertage!$B$8,AR5=Feiertage!$B$9,AR5=Feiertage!$B$10,AR5=Feiertage!$B$11,AR5=Feiertage!$B$12,AR5=Feiertage!$B$13,AR5=Feiertage!$B$14),"Feiertag","-") -> - | AV1: =IF(OR(AV5=Feiertage!$B$2,AV5=Feiertage!$B$3,AV5=Feiertage!$B$4,AV5=Feiertage!$B$5,AV5=Feiertage!$B$6,AV5=Feiertage!$B$7,AV5=Feiertage!$B$8,AV5=Feiertage!$B$9,AV5=Feiertage!$B$10,AV5=Feiertage!$B$11,AV5=Feiertage!$B$12,AV5=Feiertage!$B$13,AV5=Feiertage!$B$14),"Feiertag","-") -> - | AZ1: =IF(OR(AZ5=Feiertage!$B$2,AZ5=Feiertage!$B$3,AZ5=Feiertage!$B$4,AZ5=Feiertage!$B$5,AZ5=Feiertage!$B$6,AZ5=Feiertage!$B$7,AZ5=Feiertage!$B$8,AZ5=Feiertage!$B$9,AZ5=Feiertage!$B$10,AZ5=Feiertage!$B$11,AZ5=Feiertage!$B$12,AZ5=Feiertage!$B$13,AZ5=Feiertage!$B$14),"Feiertag","-") -> - | BD1: =IF(OR(BD5=Feiertage!$B$2,BD5=Feiertage!$B$3,BD5=Feiertage!$B$4,BD5=Feiertage!$B$5,BD5=Feiertage!$B$6,BD5=Feiertage!$B$7,BD5=Feiertage!$B$8,BD5=Feiertage!$B$9,BD5=Feiertage!$B$10,BD5=Feiertage!$B$11,BD5=Feiertage!$B$12,BD5=Feiertage!$B$13,BD5=Feiertage!$B$14),"Feiertag","-") -> - | BH1: =IF(OR(BH5=Feiertage!$B$2,BH5=Feiertage!$B$3,BH5=Feiertage!$B$4,BH5=Feiertage!$B$5,BH5=Feiertage!$B$6,BH5=Feiertage!$B$7,BH5=Feiertage!$B$8,BH5=Feiertage!$B$9,BH5=Feiertage!$B$10,BH5=Feiertage!$B$11,BH5=Feiertage!$B$12,BH5=Feiertage!$B$13,BH5=Feiertage!$B$14),"Feiertag","-") -> - | BL1: =IF(OR(BL5=Feiertage!$B$2,BL5=Feiertage!$B$3,BL5=Feiertage!$B$4,BL5=Feiertage!$B$5,BL5=Feiertage!$B$6,BL5=Feiertage!$B$7,BL5=Feiertage!$B$8,BL5=Feiertage!$B$9,BL5=Feiertage!$B$10,BL5=Feiertage!$B$11,BL5=Feiertage!$B$12,BL5=Feiertage!$B$13,BL5=Feiertage!$B$14),"Feiertag","-") -> - | BP1: =IF(OR(BP5=Feiertage!$B$2,BP5=Feiertage!$B$3,BP5=Feiertage!$B$4,BP5=Feiertage!$B$5,BP5=Feiertage!$B$6,BP5=Feiertage!$B$7,BP5=Feiertage!$B$8,BP5=Feiertage!$B$9,BP5=Feiertage!$B$10,BP5=Feiertage!$B$11,BP5=Feiertage!$B$12,BP5=Feiertage!$B$13,BP5=Feiertage!$B$14),"Feiertag","-") -> - | BT1: =IF(OR(BT5=Feiertage!$B$2,BT5=Feiertage!$B$3,BT5=Feiertage!$B$4,BT5=Feiertage!$B$5,BT5=Feiertage!$B$6,BT5=Feiertage!$B$7,BT5=Feiertage!$B$8,BT5=Feiertage!$B$9,BT5=Feiertage!$B$10,BT5=Feiertage!$B$11,BT5=Feiertage!$B$12,BT5=Feiertage!$B$13,BT5=Feiertage!$B$14),"Feiertag","-") -> - | BX1: =IF(OR(BX5=Feiertage!$B$2,BX5=Feiertage!$B$3,BX5=Feiertage!$B$4,BX5=Feiertage!$B$5,BX5=Feiertage!$B$6,BX5=Feiertage!$B$7,BX5=Feiertage!$B$8,BX5=Feiertage!$B$9,BX5=Feiertage!$B$10,BX5=Feiertage!$B$11,BX5=Feiertage!$B$12,BX5=Feiertage!$B$13,BX5=Feiertage!$B$14),"Feiertag","-") -> - | CB1: =IF(OR(CB5=Feiertage!$B$2,CB5=Feiertage!$B$3,CB5=Feiertage!$B$4,CB5=Feiertage!$B$5,CB5=Feiertage!$B$6,CB5=Feiertage!$B$7,CB5=Feiertage!$B$8,CB5=Feiertage!$B$9,CB5=Feiertage!$B$10,CB5=Feiertage!$B$11,CB5=Feiertage!$B$12,CB5=Feiertage!$B$13,CB5=Feiertage!$B$14),"Feiertag","-") -> - | CF1: =IF(OR(CF5=Feiertage!$B$2,CF5=Feiertage!$B$3,CF5=Feiertage!$B$4,CF5=Feiertage!$B$5,CF5=Feiertage!$B$6,CF5=Feiertage!$B$7,CF5=Feiertage!$B$8,CF5=Feiertage!$B$9,CF5=Feiertage!$B$10,CF5=Feiertage!$B$11,CF5=Feiertage!$B$12,CF5=Feiertage!$B$13,CF5=Feiertage!$B$14),"Feiertag","-") -> - | CJ1: =IF(OR(CJ5=Feiertage!$B$2,CJ5=Feiertage!$B$3,CJ5=Feiertage!$B$4,CJ5=Feiertage!$B$5,CJ5=Feiertage!$B$6,CJ5=Feiertage!$B$7,CJ5=Feiertage!$B$8,CJ5=Feiertage!$B$9,CJ5=Feiertage!$B$10,CJ5=Feiertage!$B$11,CJ5=Feiertage!$B$12,CJ5=Feiertage!$B$13,CJ5=Feiertage!$B$14),"Feiertag","-") -> - | CN1: =IF(OR(CN5=Feiertage!$B$2,CN5=Feiertage!$B$3,CN5=Feiertage!$B$4,CN5=Feiertage!$B$5,CN5=Feiertage!$B$6,CN5=Feiertage!$B$7,CN5=Feiertage!$B$8,CN5=Feiertage!$B$9,CN5=Feiertage!$B$10,CN5=Feiertage!$B$11,CN5=Feiertage!$B$12,CN5=Feiertage!$B$13,CN5=Feiertage!$B$14),"Feiertag","-") -> - | CR1: =IF(OR(CR5=Feiertage!$B$2,CR5=Feiertage!$B$3,CR5=Feiertage!$B$4,CR5=Feiertage!$B$5,CR5=Feiertage!$B$6,CR5=Feiertage!$B$7,CR5=Feiertage!$B$8,CR5=Feiertage!$B$9,CR5=Feiertage!$B$10,CR5=Feiertage!$B$11,CR5=Feiertage!$B$12,CR5=Feiertage!$B$13,CR5=Feiertage!$B$14),"Feiertag","-") -> - | CV1: =IF(OR(CV5=Feiertage!$B$2,CV5=Feiertage!$B$3,CV5=Feiertage!$B$4,CV5=Feiertage!$B$5,CV5=Feiertage!$B$6,CV5=Feiertage!$B$7,CV5=Feiertage!$B$8,CV5=Feiertage!$B$9,CV5=Feiertage!$B$10,CV5=Feiertage!$B$11,CV5=Feiertage!$B$12,CV5=Feiertage!$B$13,CV5=Feiertage!$B$14),"Feiertag","-") -> - | CZ1: =IF(OR(CZ5=Feiertage!$B$2,CZ5=Feiertage!$B$3,CZ5=Feiertage!$B$4,CZ5=Feiertage!$B$5,CZ5=Feiertage!$B$6,CZ5=Feiertage!$B$7,CZ5=Feiertage!$B$8,CZ5=Feiertage!$B$9,CZ5=Feiertage!$B$10,CZ5=Feiertage!$B$11,CZ5=Feiertage!$B$12,CZ5=Feiertage!$B$13,CZ5=Feiertage!$B$14),"Feiertag","-") -> - | DD1: =IF(OR(DD5=Feiertage!$B$2,DD5=Feiertage!$B$3,DD5=Feiertage!$B$4,DD5=Feiertage!$B$5,DD5=Feiertage!$B$6,DD5=Feiertage!$B$7,DD5=Feiertage!$B$8,DD5=Feiertage!$B$9,DD5=Feiertage!$B$10,DD5=Feiertage!$B$11,DD5=Feiertage!$B$12,DD5=Feiertage!$B$13,DD5=Feiertage!$B$14),"Feiertag","-") -> - | DH1: =IF(OR(DH5=Feiertage!$B$2,DH5=Feiertage!$B$3,DH5=Feiertage!$B$4,DH5=Feiertage!$B$5,DH5=Feiertage!$B$6,DH5=Feiertage!$B$7,DH5=Feiertage!$B$8,DH5=Feiertage!$B$9,DH5=Feiertage!$B$10,DH5=Feiertage!$B$11,DH5=Feiertage!$B$12,DH5=Feiertage!$B$13,DH5=Feiertage!$B$14),"Feiertag","-") -> - | DL1: =IF(OR(DL5=Feiertage!$B$2,DL5=Feiertage!$B$3,DL5=Feiertage!$B$4,DL5=Feiertage!$B$5,DL5=Feiertage!$B$6,DL5=Feiertage!$B$7,DL5=Feiertage!$B$8,DL5=Feiertage!$B$9,DL5=Feiertage!$B$10,DL5=Feiertage!$B$11,DL5=Feiertage!$B$12,DL5=Feiertage!$B$13,DL5=Feiertage!$B$14),"Feiertag","-") -> - | DP1: =IF(OR(DP5=Feiertage!$B$2,DP5=Feiertage!$B$3,DP5=Feiertage!$B$4,DP5=Feiertage!$B$5,DP5=Feiertage!$B$6,DP5=Feiertage!$B$7,DP5=Feiertage!$B$8,DP5=Feiertage!$B$9,DP5=Feiertage!$B$10,DP5=Feiertage!$B$11,DP5=Feiertage!$B$12,DP5=Feiertage!$B$13,DP5=Feiertage!$B$14),"Feiertag","-") -> - | DT1: =IF(OR(DT5=Feiertage!$B$2,DT5=Feiertage!$B$3,DT5=Feiertage!$B$4,DT5=Feiertage!$B$5,DT5=Feiertage!$B$6,DT5=Feiertage!$B$7,DT5=Feiertage!$B$8,DT5=Feiertage!$B$9,DT5=Feiertage!$B$10,DT5=Feiertage!$B$11,DT5=Feiertage!$B$12,DT5=Feiertage!$B$13,DT5=Feiertage!$B$14),"Feiertag","-") -> - | DX1: =IF(OR(DX5=Feiertage!$B$2,DX5=Feiertage!$B$3,DX5=Feiertage!$B$4,DX5=Feiertage!$B$5,DX5=Feiertage!$B$6,DX5=Feiertage!$B$7,DX5=Feiertage!$B$8,DX5=Feiertage!$B$9,DX5=Feiertage!$B$10,DX5=Feiertage!$B$11,DX5=Feiertage!$B$12,DX5=Feiertage!$B$13,DX5=Feiertage!$B$14),"Feiertag","-") -> -
A2: Monat | B2: Juli | C2: =B2 -> Juli | D2: Mo. - Fr. | E2: =IF(B6="Sommer [m.S.]",SUM(SommermS),IF(B6="Winter [m.S.]",SUM(WintermS),IF(B6="Sommer [o.S.]",SUM(SommeroS),IF(B6="Winter [o.S.]",SUM(WinteroS))))) -> #NAME? | F2: =IF(B6="Sommer [o.S.]",SUM(SommeroS),IF(B6="Winter [o.S.]",SUM(WinteroS),SUM(SommeroS))) -> #NAME? | G2: Prüfung | H2: =IF(AND(OR(H6="Montag",H6="Dienstag",H6="Mittwoch",H6="Donnerstag",H6="Freitag"),H4="Schule",$E$2=H30),"ok",IF(AND(H4="schulfrei",H30=$F$2),"ok",IF(AND(H6="Samstag",$E$3=H30),"ok",IF(AND(H6="Sonntag",$E$4=H30),"ok",IF(AND(H1="Feiertag",$E$5=H30),"ok","prüfen"))))) -> #NAME? | L2: =IF(AND(OR(L6="Montag",L6="Dienstag",L6="Mittwoch",L6="Donnerstag",L6="Freitag"),L4="Schule",$E$2=L30),"ok",IF(AND(L4="schulfrei",L30=$F$2),"ok",IF(AND(L6="Samstag",$E$3=L30),"ok",IF(AND(L6="Sonntag",$E$4=L30),"ok",IF(AND(L1="Feiertag",$E$5=L30),"ok","prüfen"))))) -> #NAME? | P2: =IF(AND(OR(P6="Montag",P6="Dienstag",P6="Mittwoch",P6="Donnerstag",P6="Freitag"),P4="Schule",$E$2=P30),"ok",IF(AND(P4="schulfrei",P30=$F$2),"ok",IF(AND(P6="Samstag",$E$3=P30),"ok",IF(AND(P6="Sonntag",$E$4=P30),"ok",IF(AND(P1="Feiertag",$E$5=P30),"ok","prüfen"))))) -> #NAME? | T2: =IF(AND(OR(T6="Montag",T6="Dienstag",T6="Mittwoch",T6="Donnerstag",T6="Freitag"),T4="Schule",$E$2=T30),"ok",IF(AND(T4="schulfrei",T30=$F$2),"ok",IF(AND(T6="Samstag",$E$3=T30),"ok",IF(AND(T6="Sonntag",$E$4=T30),"ok",IF(AND(T1="Feiertag",$E$5=T30),"ok","prüfen"))))) -> #NAME? | X2: =IF(AND(OR(X6="Montag",X6="Dienstag",X6="Mittwoch",X6="Donnerstag",X6="Freitag"),X4="Schule",$E$2=X30),"ok",IF(AND(X4="schulfrei",X30=$F$2),"ok",IF(AND(X6="Samstag",$E$3=X30),"ok",IF(AND(X6="Sonntag",$E$4=X30),"ok",IF(AND(X1="Feiertag",$E$5=X30),"ok","prüfen"))))) -> #NAME? | AB2: =IF(AND(OR(AB6="Montag",AB6="Dienstag",AB6="Mittwoch",AB6="Donnerstag",AB6="Freitag"),AB4="Schule",$E$2=AB30),"ok",IF(AND(AB4="schulfrei",AB30=$F$2),"ok",IF(AND(AB6="Samstag",$E$3=AB30),"ok",IF(AND(AB6="Sonntag",$E$4=AB30),"ok",IF(AND(AB1="Feiertag",$E$5=AB30),"ok","prüfen"))))) -> #NAME? | AF2: =IF(AND(OR(AF6="Montag",AF6="Dienstag",AF6="Mittwoch",AF6="Donnerstag",AF6="Freitag"),AF4="Schule",$E$2=AF30),"ok",IF(AND(AF4="schulfrei",AF30=$F$2),"ok",IF(AND(AF6="Samstag",$E$3=AF30),"ok",IF(AND(AF6="Sonntag",$E$4=AF30),"ok",IF(AND(AF1="Feiertag",$E$5=AF30),"ok","prüfen"))))) -> #NAME? | AJ2: =IF(AND(OR(AJ6="Montag",AJ6="Dienstag",AJ6="Mittwoch",AJ6="Donnerstag",AJ6="Freitag"),AJ4="Schule",$E$2=AJ30),"ok",IF(AND(AJ4="schulfrei",AJ30=$F$2),"ok",IF(AND(AJ6="Samstag",$E$3=AJ30),"ok",IF(AND(AJ6="Sonntag",$E$4=AJ30),"ok",IF(AND(AJ1="Feiertag",$E$5=AJ30),"ok","prüfen"))))) -> #NAME? | AN2: =IF(AND(OR(AN6="Montag",AN6="Dienstag",AN6="Mittwoch",AN6="Donnerstag",AN6="Freitag"),AN4="Schule",$E$2=AN30),"ok",IF(AND(AN4="schulfrei",AN30=$F$2),"ok",IF(AND(AN6="Samstag",$E$3=AN30),"ok",IF(AND(AN6="Sonntag",$E$4=AN30),"ok",IF(AND(AN1="Feiertag",$E$5=AN30),"ok","prüfen"))))) -> #NAME? | AR2: =IF(AND(OR(AR6="Montag",AR6="Dienstag",AR6="Mittwoch",AR6="Donnerstag",AR6="Freitag"),AR4="Schule",$E$2=AR30),"ok",IF(AND(AR4="schulfrei",AR30=$F$2),"ok",IF(AND(AR6="Samstag",$E$3=AR30),"ok",IF(AND(AR6="Sonntag",$E$4=AR30),"ok",IF(AND(AR1="Feiertag",$E$5=AR30),"ok","prüfen"))))) -> #NAME? | AV2: =IF(AND(OR(AV6="Montag",AV6="Dienstag",AV6="Mittwoch",AV6="Donnerstag",AV6="Freitag"),AV4="Schule",$E$2=AV30),"ok",IF(AND(AV4="schulfrei",AV30=$F$2),"ok",IF(AND(AV6="Samstag",$E$3=AV30),"ok",IF(AND(AV6="Sonntag",$E$4=AV30),"ok",IF(AND(AV1="Feiertag",$E$5=AV30),"ok","prüfen"))))) -> #NAME? | AZ2: =IF(AND(OR(AZ6="Montag",AZ6="Dienstag",AZ6="Mittwoch",AZ6="Donnerstag",AZ6="Freitag"),AZ4="Schule",$E$2=AZ30),"ok",IF(AND(AZ4="schulfrei",AZ30=$F$2),"ok",IF(AND(AZ6="Samstag",$E$3=AZ30),"ok",IF(AND(AZ6="Sonntag",$E$4=AZ30),"ok",IF(AND(AZ1="Feiertag",$E$5=AZ30),"ok","prüfen"))))) -> #NAME? | BD2: =IF(AND(OR(BD6="Montag",BD6="Dienstag",BD6="Mittwoch",BD6="Donnerstag",BD6="Freitag"),BD4="Schule",$E$2=BD30),"ok",IF(AND(BD4="schulfrei",BD30=$F$2),"ok",IF(AND(BD6="Samstag",$E$3=BD30),"ok",IF(AND(BD6="Sonntag",$E$4=BD30),"ok",IF(AND(BD1="Feiertag",$E$5=BD30),"ok","prüfen"))))) -> #NAME? | BH2: =IF(AND(OR(BH6="Montag",BH6="Dienstag",BH6="Mittwoch",BH6="Donnerstag",BH6="Freitag"),BH4="Schule",$E$2=BH30),"ok",IF(AND(BH4="schulfrei",BH30=$F$2),"ok",IF(AND(BH6="Samstag",$E$3=BH30),"ok",IF(AND(BH6="Sonntag",$E$4=BH30),"ok",IF(AND(BH1="Feiertag",$E$5=BH30),"ok","prüfen"))))) -> #NAME? | BL2: =IF(AND(OR(BL6="Montag",BL6="Dienstag",BL6="Mittwoch",BL6="Donnerstag",BL6="Freitag"),BL4="Schule",$E$2=BL30),"ok",IF(AND(BL4="schulfrei",BL30=$F$2),"ok",IF(AND(BL6="Samstag",$E$3=BL30),"ok",IF(AND(BL6="Sonntag",$E$4=BL30),"ok",IF(AND(BL1="Feiertag",$E$5=BL30),"ok","prüfen"))))) -> #NAME? | BP2: =IF(AND(OR(BP6="Montag",BP6="Dienstag",BP6="Mittwoch",BP6="Donnerstag",BP6="Freitag"),BP4="Schule",$E$2=BP30),"ok",IF(AND(BP4="schulfrei",BP30=$F$2),"ok",IF(AND(BP6="Samstag",$E$3=BP30),"ok",IF(AND(BP6="Sonntag",$E$4=BP30),"ok",IF(AND(BP1="Feiertag",$E$5=BP30),"ok","prüfen"))))) -> #NAME? | BT2: =IF(AND(OR(BT6="Montag",BT6="Dienstag",BT6="Mittwoch",BT6="Donnerstag",BT6="Freitag"),BT4="Schule",$E$2=BT30),"ok",IF(AND(BT4="schulfrei",BT30=$F$2),"ok",IF(AND(BT6="Samstag",$E$3=BT30),"ok",IF(AND(BT6="Sonntag",$E$4=BT30),"ok",IF(AND(BT1="Feiertag",$E$5=BT30),"ok","prüfen"))))) -> #NAME? | BX2: =IF(AND(OR(BX6="Montag",BX6="Dienstag",BX6="Mittwoch",BX6="Donnerstag",BX6="Freitag"),BX4="Schule",$E$2=BX30),"ok",IF(AND(BX4="schulfrei",BX30=$F$2),"ok",IF(AND(BX6="Samstag",$E$3=BX30),"ok",IF(AND(BX6="Sonntag",$E$4=BX30),"ok",IF(AND(BX1="Feiertag",$E$5=BX30),"ok","prüfen"))))) -> #NAME? | CB2: =IF(AND(OR(CB6="Montag",CB6="Dienstag",CB6="Mittwoch",CB6="Donnerstag",CB6="Freitag"),CB4="Schule",$E$2=CB30),"ok",IF(AND(CB4="schulfrei",CB30=$F$2),"ok",IF(AND(CB6="Samstag",$E$3=CB30),"ok",IF(AND(CB6="Sonntag",$E$4=CB30),"ok",IF(AND(CB1="Feiertag",$E$5=CB30),"ok","prüfen"))))) -> #NAME? | CF2: =IF(AND(OR(CF6="Montag",CF6="Dienstag",CF6="Mittwoch",CF6="Donnerstag",CF6="Freitag"),CF4="Schule",$E$2=CF30),"ok",IF(AND(CF4="schulfrei",CF30=$F$2),"ok",IF(AND(CF6="Samstag",$E$3=CF30),"ok",IF(AND(CF6="Sonntag",$E$4=CF30),"ok",IF(AND(CF1="Feiertag",$E$5=CF30),"ok","prüfen"))))) -> #NAME? | CJ2: =IF(AND(OR(CJ6="Montag",CJ6="Dienstag",CJ6="Mittwoch",CJ6="Donnerstag",CJ6="Freitag"),CJ4="Schule",$E$2=CJ30),"ok",IF(AND(CJ4="schulfrei",CJ30=$F$2),"ok",IF(AND(CJ6="Samstag",$E$3=CJ30),"ok",IF(AND(CJ6="Sonntag",$E$4=CJ30),"ok",IF(AND(CJ1="Feiertag",$E$5=CJ30),"ok","prüfen"))))) -> #NAME? | CN2: =IF(AND(OR(CN6="Montag",CN6="Dienstag",CN6="Mittwoch",CN6="Donnerstag",CN6="Freitag"),CN4="Schule",$E$2=CN30),"ok",IF(AND(CN4="schulfrei",CN30=$F$2),"ok",IF(AND(CN6="Samstag",$E$3=CN30),"ok",IF(AND(CN6="Sonntag",$E$4=CN30),"ok",IF(AND(CN1="Feiertag",$E$5=CN30),"ok","prüfen"))))) -> #NAME? | CR2: =IF(AND(OR(CR6="Montag",CR6="Dienstag",CR6="Mittwoch",CR6="Donnerstag",CR6="Freitag"),CR4="Schule",$E$2=CR30),"ok",IF(AND(CR4="schulfrei",CR30=$F$2),"ok",IF(AND(CR6="Samstag",$E$3=CR30),"ok",IF(AND(CR6="Sonntag",$E$4=CR30),"ok",IF(AND(CR1="Feiertag",$E$5=CR30),"ok","prüfen"))))) -> #NAME? | CV2: =IF(AND(OR(CV6="Montag",CV6="Dienstag",CV6="Mittwoch",CV6="Donnerstag",CV6="Freitag"),CV4="Schule",$E$2=CV30),"ok",IF(AND(CV4="schulfrei",CV30=$F$2),"ok",IF(AND(CV6="Samstag",$E$3=CV30),"ok",IF(AND(CV6="Sonntag",$E$4=CV30),"ok",IF(AND(CV1="Feiertag",$E$5=CV30),"ok","prüfen"))))) -> #NAME? | CZ2: =IF(AND(OR(CZ6="Montag",CZ6="Dienstag",CZ6="Mittwoch",CZ6="Donnerstag",CZ6="Freitag"),CZ4="Schule",$E$2=CZ30),"ok",IF(AND(CZ4="schulfrei",CZ30=$F$2),"ok",IF(AND(CZ6="Samstag",$E$3=CZ30),"ok",IF(AND(CZ6="Sonntag",$E$4=CZ30),"ok",IF(AND(CZ1="Feiertag",$E$5=CZ30),"ok","prüfen"))))) -> #NAME? | DD2: =IF(AND(OR(DD6="Montag",DD6="Dienstag",DD6="Mittwoch",DD6="Donnerstag",DD6="Freitag"),DD4="Schule",$E$2=DD30),"ok",IF(AND(DD4="schulfrei",DD30=$F$2),"ok",IF(AND(DD6="Samstag",$E$3=DD30),"ok",IF(AND(DD6="Sonntag",$E$4=DD30),"ok",IF(AND(DD1="Feiertag",$E$5=DD30),"ok","prüfen"))))) -> #NAME? | DH2: =IF(AND(OR(DH6="Montag",DH6="Dienstag",DH6="Mittwoch",DH6="Donnerstag",DH6="Freitag"),DH4="Schule",$E$2=DH30),"ok",IF(AND(DH4="schulfrei",DH30=$F$2),"ok",IF(AND(DH6="Samstag",$E$3=DH30),"ok",IF(AND(DH6="Sonntag",$E$4=DH30),"ok",IF(AND(DH1="Feiertag",$E$5=DH30),"ok","prüfen"))))) -> #NAME? | DL2: =IF(AND(OR(DL6="Montag",DL6="Dienstag",DL6="Mittwoch",DL6="Donnerstag",DL6="Freitag"),DL4="Schule",$E$2=DL30),"ok",IF(AND(DL4="schulfrei",DL30=$F$2),"ok",IF(AND(DL6="Samstag",$E$3=DL30),"ok",IF(AND(DL6="Sonntag",$E$4=DL30),"ok",IF(AND(DL1="Feiertag",$E$5=DL30),"ok","prüfen"))))) -> #NAME? | DP2: =IF(AND(OR(DP6="Montag",DP6="Dienstag",DP6="Mittwoch",DP6="Donnerstag",DP6="Freitag"),DP4="Schule",$E$2=DP30),"ok",IF(AND(DP4="schulfrei",DP30=$F$2),"ok",IF(AND(DP6="Samstag",$E$3=DP30),"ok",IF(AND(DP6="Sonntag",$E$4=DP30),"ok",IF(AND(DP1="Feiertag",$E$5=DP30),"ok","prüfen"))))) -> #NAME? | DT2: =IF(AND(OR(DT6="Montag",DT6="Dienstag",DT6="Mittwoch",DT6="Donnerstag",DT6="Freitag"),DT4="Schule",$E$2=DT30),"ok",IF(AND(DT4="schulfrei",DT30=$F$2),"ok",IF(AND(DT6="Samstag",$E$3=DT30),"ok",IF(AND(DT6="Sonntag",$E$4=DT30),"ok",IF(AND(DT1="Feiertag",$E$5=DT30),"ok","prüfen"))))) -> #NAME? | DX2: =IF(AND(OR(DX6="Montag",DX6="Dienstag",DX6="Mittwoch",DX6="Donnerstag",DX6="Freitag"),DX4="Schule",$E$2=DX30),"ok",IF(AND(DX4="schulfrei",DX30=$F$2),"ok",IF(AND(DX6="Samstag",$E$3=DX30),"ok",IF(AND(DX6="Sonntag",$E$4=DX30),"ok",IF(AND(DX1="Feiertag",$E$5=DX30),"ok","prüfen"))))) -> #NAME?
A3: Jahr | B3: 2025 | D3: Samstag | E3: =SUM(Dienste!C33:C34) -> 0.80069444 | F3: 0 | G3: 414 - geteilt | H3: nein | L3: nein | P3: nein | T3: nein | X3: nein | AB3: nein | AF3: nein | AJ3: nein | AN3: nein | AR3: nein | AV3: nein | AZ3: nein | BD3: nein | BH3: nein | BL3: nein | BP3: nein | BT3: nein | BX3: nein | CB3: nein | CF3: nein | CJ3: nein | CN3: nein | CR3: nein | CV3: nein | CZ3: nein | DD3: nein | DH3: nein | DL3: nein | DP3: nein | DT3: nein | DX3: nein
A4: Gesamtstunden | B4: =SUM(C8:C28) -> 21.646528 | D4: Sonntag | E4: 0 | F4: 0 | G4: mS / oS | H4: Schule | L4: Schule | P4: Schule | T4: Schule | X4: Schule | AB4: Schule | AF4: schulfrei | AJ4: schulfrei | AN4: schulfrei | AR4: schulfrei | AV4: schulfrei | AZ4: Schule | BD4: Schule | BH4: schulfrei | BL4: schulfrei | BP4: schulfrei | BT4: schulfrei | BX4: schulfrei | CB4: Schule | CF4: Schule | CJ4: schulfrei | CN4: schulfrei | CR4: schulfrei | CV4: schulfrei | CZ4: schulfrei | DD4: Schule | DH4: Schule | DL4: schulfrei | DP4: schulfrei | DT4: schulfrei | DX4: schulfrei
A5: Dienstplan beginnt am: | B5: 45839 | D5: Feiertag | E5: =Lenker!D23 -> 5.1378464 | F5: =Lenker!D23 -> 5.1378464 | G5: Datum | H5: =B5 -> 45839 | L5: =H5+1 -> 45840 | P5: =L5+1 -> 45841 | T5: =P5+1 -> 45842 | X5: =T5+1 -> 45843 | AB5: =X5+1 -> 45844 | AF5: =AB5+1 -> 45845 | AJ5: =AF5+1 -> 45846 | AN5: =AJ5+1 -> 45847 | AR5: =AN5+1 -> 45848 | AV5: =AR5+1 -> 45849 | AZ5: =AV5+1 -> 45850 | BD5: =AZ5+1 -> 45851 | BH5: =BD5+1 -> 45852 | BL5: =BH5+1 -> 45853 | BP5: =BL5+1 -> 45854 | BT5: =BP5+1 -> 45855 | BX5: =BT5+1 -> 45856 | CB5: =BX5+1 -> 45857 | CF5: =CB5+1 -> 45858 | CJ5: =CF5+1 -> 45859 | CN5: =CJ5+1 -> 45860 | CR5: =CN5+1 -> 45861 | CV5: =CR5+1 -> 45862 | CZ5: =CV5+1 -> 45863 | DD5: =CZ5+1 -> 45864 | DH5: =DD5+1 -> 45865 | DL5: =DH5+1 -> 45866 | DP5: =DL5+1 -> 45867 | DT5: =DP5+1 -> 45868 | DX5: =DT5+1 -> 45869
A6: Dienstplan gilt für: | B6: Sommer [m.S.] | C6: * schulfreie Tage sind nur werktags zu definieren. | G6: Wochentag | H6: =TEXT(H5,"TTTT") -> TTTT | L6: =TEXT(L5,"TTTT") -> TTTT | P6: =TEXT(P5,"TTTT") -> TTTT | T6: =TEXT(T5,"TTTT") -> TTTT | X6: =TEXT(X5,"TTTT") -> TTTT | AB6: =TEXT(AB5,"TTTT") -> TTTT | AF6: =TEXT(AF5,"TTTT") -> TTTT | AJ6: =TEXT(AJ5,"TTTT") -> TTTT | AN6: =TEXT(AN5,"TTTT") -> TTTT | AR6: =TEXT(AR5,"TTTT") -> TTTT | AV6: =TEXT(AV5,"TTTT") -> TTTT | AZ6: =TEXT(AZ5,"TTTT") -> TTTT | BD6: =TEXT(BD5,"TTTT") -> TTTT | BH6: =TEXT(BH5,"TTTT") -> TTTT | BL6: =TEXT(BL5,"TTTT") -> TTTT | BP6: =TEXT(BP5,"TTTT") -> TTTT | BT6: =TEXT(BT5,"TTTT") -> TTTT | BX6: =TEXT(BX5,"TTTT") -> TTTT | CB6: =TEXT(CB5,"TTTT") -> TTTT | CF6: =TEXT(CF5,"TTTT") -> TTTT | CJ6: =TEXT(CJ5,"TTTT") -> TTTT | CN6: =TEXT(CN5,"TTTT") -> TTTT | CR6: =TEXT(CR5,"TTTT") -> TTTT | CV6: =TEXT(CV5,"TTTT") -> TTTT | CZ6: =TEXT(CZ5,"TTTT") -> TTTT | DD6: =TEXT(DD5,"TTTT") -> TTTT | DH6: =TEXT(DH5,"TTTT") -> TTTT | DL6: =TEXT(DL5,"TTTT") -> TTTT | DP6: =TEXT(DP5,"TTTT") -> TTTT | DT6: =TEXT(DT5,"TTTT") -> TTTT | DX6: =TEXT(DX5,"TTTT") -> TTTT
A7: Lenker | B7: LD / RD / km | C7: Ist-Std. | D7: Urlaub [konsum.] | E7: Resturlaub | F7: Korr. - Zeiten | G7: Korr. - Diäten | H7: Dienst | I7: VAD | J7: Diäten | K7: km | L7: Dienst | M7: VAD | N7: Diäten | O7: km | P7: Dienst | Q7: VAD | R7: Diäten | S7: km | T7: Dienst | U7: VAD | V7: Diäten | W7: km | X7: Dienst | Y7: VAD | Z7: Diäten | AA7: km | AB7: Dienst | AC7: VAD | AD7: Diäten | AE7: km | AF7: Dienst | AG7: VAD | AH7: Diäten | AI7: km | AJ7: Dienst | AK7: VAD | AL7: Diäten | AM7: km | AN7: Dienst | AO7: VAD | AP7: Diäten | AQ7: km | AR7: Dienst | AS7: VAD | AT7: Diäten | AU7: km | AV7: Dienst | AW7: VAD | AX7: Diäten | AY7: km | AZ7: Dienst | BA7: VAD | BB7: Diäten | BC7: km | BD7: Dienst | BE7: VAD | BF7: Diäten | BG7: km | BH7: Dienst | BI7: VAD | BJ7: Diäten | BK7: km | BL7: Dienst | BM7: VAD | BN7: Diäten | BO7: km | BP7: Dienst | BQ7: VAD | BR7: Diäten | BS7: km | BT7: Dienst | BU7: VAD | BV7: Diäten | BW7: km | BX7: Dienst | BY7: VAD | BZ7: Diäten | CA7: km | CB7: Dienst | CC7: VAD | CD7: Diäten | CE7: km | CF7: Dienst | CG7: VAD | CH7: Diäten | CI7: km | CJ7: Dienst | CK7: VAD | CL7: Diäten | CM7: km | CN7: Dienst | CO7: VAD | CP7: Diäten | CQ7: km | CR7: Dienst | CS7: VAD | CT7: Diäten | CU7: km | CV7: Dienst | CW7: VAD | CX7: Diäten | CY7: km | CZ7: Dienst | DA7: VAD | DB7: Diäten | DC7: km | DD7: Dienst | DE7: VAD | DF7: Diäten | DG7: km | DH7: Dienst | DI7: VAD | DJ7: Diäten | DK7: km | DL7: Dienst | DM7: VAD | DN7: Diäten | DO7: km | DP7: Dienst | DQ7: VAD | DR7: Diäten | DS7: km | DT7: Dienst | DU7: VAD | DV7: Diäten | DW7: km | DX7: Dienst | DY7: VAD | DZ7: Diäten | EA7: km
A8: =IF(ISERROR(Lenker!A2),"N.N.",Lenker!A2) -> Blaskovic, Nenad | B8: =(SUM(J8,N8,R8,V8,Z8,AD8,AH8,AL8,AP8,AT8,AX8,BB8,BF8,BJ8,BN8,BR8,BV8,BZ8,CD8,CH8,CL8,CP8,CT8,CX8,DB8,DF8,DJ8,DN8,DR8,DV8,DZ8)-(IF(H8="SOF",J8,0)+IF(L8="SOF",N8,0)+IF(P8="SOF",R8,0)+IF(T8="SOF",V8,0)+IF(X8="SOF",Z8,0)+IF(AB8="SOF",AD8,0)+IF(AF8="SOF",AH8,0)+IF(AJ8="SOF",AL8,0)+IF(AN8="SOF",AP8,0)+IF(AR8="SOF",AT8,0)+IF(AV8="SOF",AX8,0)+IF(AZ8="SOF",BB8,0)+IF(BD8="SOF",BF8,0)+IF(BH8="SOF",BJ8,0)+IF(BL8="SOF",BN8,0)+IF(BP8="SOF",BR8,0)+IF(BT8="SOF",BV8,0)+IF(BX8="SOF",BZ8,0)+IF(CB8="SOF",CD8,0)+IF(CF8="SOF",CH8,0)+IF(CJ8="SOF",CL8,0)+IF(CN8="SOF",CP8,0)+IF(CR8="SOF",CT8,0)+IF(CV8="SOF",CX8,0)+IF(CZ8="SOF",DB8,0)+IF(DD8="SOF",DF8,0)+IF(DH8="SOF",DJ8,0)+IF(DL8="SOF",DN8,0)+IF(DP8="SOF",DR8,0)+IF(DT8="SOF",DV8,0)+IF(DX8="SOF",DZ8,0)))+G8&" / "&(IF(H8="SOF",J8,0)+IF(L8="SOF",N8,0)+IF(P8="SOF",R8,0)+IF(T8="SOF",V8,0)+IF(X8="SOF",Z8,0)+IF(AB8="SOF",AD8,0)+IF(AF8="SOF",AH8,0)+IF(AJ8="SOF",AL8,0)+IF(AN8="SOF",AP8,0)+IF(AR8="SOF",AT8,0)+IF(AV8="SOF",AX8,0)+IF(AZ8="SOF",BB8,0)+IF(BD8="SOF",BF8,0)+IF(BH8="SOF",BJ8,0)+IF(BL8="SOF",BN8,0)+IF(BP8="SOF",BR8,0)+IF(BT8="SOF",BV8,0)+IF(BX8="SOF",BZ8,0)+IF(CB8="SOF",CD8,0)+IF(CF8="SOF",CH8,0)+IF(CJ8="SOF",CL8,0)+IF(CN8="SOF",CP8,0)+IF(CR8="SOF",CT8,0)+IF(CV8="SOF",CX8,0)+IF(CZ8="SOF",DB8,0)+IF(DD8="SOF",DF8,0)+IF(DH8="SOF",DJ8,0)+IF(DL8="SOF",DN8,0)+IF(DP8="SOF",DR8,0)+IF(DT8="SOF",DV8,0)+IF(DX8="SOF",DZ8,0))&" / "&SUM(K8,O8,S8,W8,AA8,AE8,AI8,AM8,AQ8,AU8,AY8,BC8,BG8,BK8,BO8,BS8,BW8,CA8,CE8,CI8,CM8,CQ8,CU8,CY8,DC8,DG8,DK8,DO8,DS8,DW8,EA8) -> 20 / 0 / 0 | C8: =(SUM(I8,M8,Q8,U8,Y8,AC8,AG8,AK8,AO8,AS8,AW8,BA8,BE8,BI8,BM8,BQ8,BU8,BY8,CC8,CG8,CK8,CO8,CS8,CW8,DA8,DE8,DI8,DM8,DQ8,DU8,DY8))+F8 -> 0.41666667 | D8: 0 | E8: 3,55 Tage | AF8: F | AG8: 0:00 | AH8: 0 | AJ8: F | AK8: 0:00 | AL8: 0 | AN8: F | AO8: 0:00 | AP8: 0 | AR8: F | AS8: 0:00 | AT8: 0 | AV8: F | AW8: 0:00 | AX8: 0 | AZ8: 451SA | BA8: 10:00 | BB8: 10 | BF8: 0 | BH8: F | BI8: 0 | BL8: F | BM8: 0 | BP8: F | BQ8: 0 | BT8: F | BU8: 0 | BX8: F | BY8: 0 | CB8: 451SA | CC8: 0.41666667 | CD8: 10
A9: =IF(ISERROR(Lenker!A3),"N.N.",Lenker!A3) -> Fröhlacher, Hubert | B9: =(SUM(J9,N9,R9,V9,Z9,AD9,AH9,AL9,AP9,AT9,AX9,BB9,BF9,BJ9,BN9,BR9,BV9,BZ9,CD9,CH9,CL9,CP9,CT9,CX9,DB9,DF9,DJ9,DN9,DR9,DV9,DZ9)-(IF(H9="SOF",J9,0)+IF(L9="SOF",N9,0)+IF(P9="SOF",R9,0)+IF(T9="SOF",V9,0)+IF(X9="SOF",Z9,0)+IF(AB9="SOF",AD9,0)+IF(AF9="SOF",AH9,0)+IF(AJ9="SOF",AL9,0)+IF(AN9="SOF",AP9,0)+IF(AR9="SOF",AT9,0)+IF(AV9="SOF",AX9,0)+IF(AZ9="SOF",BB9,0)+IF(BD9="SOF",BF9,0)+IF(BH9="SOF",BJ9,0)+IF(BL9="SOF",BN9,0)+IF(BP9="SOF",BR9,0)+IF(BT9="SOF",BV9,0)+IF(BX9="SOF",BZ9,0)+IF(CB9="SOF",CD9,0)+IF(CF9="SOF",CH9,0)+IF(CJ9="SOF",CL9,0)+IF(CN9="SOF",CP9,0)+IF(CR9="SOF",CT9,0)+IF(CV9="SOF",CX9,0)+IF(CZ9="SOF",DB9,0)+IF(DD9="SOF",DF9,0)+IF(DH9="SOF",DJ9,0)+IF(DL9="SOF",DN9,0)+IF(DP9="SOF",DR9,0)+IF(DT9="SOF",DV9,0)+IF(DX9="SOF",DZ9,0)))+G9&" / "&(IF(H9="SOF",J9,0)+IF(L9="SOF",N9,0)+IF(P9="SOF",R9,0)+IF(T9="SOF",V9,0)+IF(X9="SOF",Z9,0)+IF(AB9="SOF",AD9,0)+IF(AF9="SOF",AH9,0)+IF(AJ9="SOF",AL9,0)+IF(AN9="SOF",AP9,0)+IF(AR9="SOF",AT9,0)+IF(AV9="SOF",AX9,0)+IF(AZ9="SOF",BB9,0)+IF(BD9="SOF",BF9,0)+IF(BH9="SOF",BJ9,0)+IF(BL9="SOF",BN9,0)+IF(BP9="SOF",BR9,0)+IF(BT9="SOF",BV9,0)+IF(BX9="SOF",BZ9,0)+IF(CB9="SOF",CD9,0)+IF(CF9="SOF",CH9,0)+IF(CJ9="SOF",CL9,0)+IF(CN9="SOF",CP9,0)+IF(CR9="SOF",CT9,0)+IF(CV9="SOF",CX9,0)+IF(CZ9="SOF",DB9,0)+IF(DD9="SOF",DF9,0)+IF(DH9="SOF",DJ9,0)+IF(DL9="SOF",DN9,0)+IF(DP9="SOF",DR9,0)+IF(DT9="SOF",DV9,0)+IF(DX9="SOF",DZ9,0))&" / "&SUM(K9,O9,S9,W9,AA9,AE9,AI9,AM9,AQ9,AU9,AY9,BC9,BG9,BK9,BO9,BS9,BW9,CA9,CE9,CI9,CM9,CQ9,CU9,CY9,DC9,DG9,DK9,DO9,DS9,DW9,EA9) -> 33 / 0 / 0 | C9: =(SUM(I9,M9,Q9,U9,Y9,AC9,AG9,AK9,AO9,AS9,AW9,BA9,BE9,BI9,BM9,BQ9,BU9,BY9,CC9,CG9,CK9,CO9,CS9,CW9,DA9,DE9,DI9,DM9,DQ9,DU9,DY9))+F9 -> 0.95833333 | D9: 0 | E9: 26 Tage | AH9: 0 | AL9: 0 | AP9: 0 | AR9: 436oS-TAF | AS9: 10:00 | AT9: 10 | AX9: 0 | BB9: 0 | BF9: 0 | BT9: 435oS-HOF | BU9: 0.5 | BV9: 12 | BX9: 437oS | BY9: 0.45833333 | BZ9: 11
A10: =IF(ISERROR(Lenker!A4),"N.N.",Lenker!A4) -> Genäuß, Thomas | B10: =(SUM(J10,N10,R10,V10,Z10,AD10,AH10,AL10,AP10,AT10,AX10,BB10,BF10,BJ10,BN10,BR10,BV10,BZ10,CD10,CH10,CL10,CP10,CT10,CX10,DB10,DF10,DJ10,DN10,DR10,DV10,DZ10)-(IF(H10="SOF",J10,0)+IF(L10="SOF",N10,0)+IF(P10="SOF",R10,0)+IF(T10="SOF",V10,0)+IF(X10="SOF",Z10,0)+IF(AB10="SOF",AD10,0)+IF(AF10="SOF",AH10,0)+IF(AJ10="SOF",AL10,0)+IF(AN10="SOF",AP10,0)+IF(AR10="SOF",AT10,0)+IF(AV10="SOF",AX10,0)+IF(AZ10="SOF",BB10,0)+IF(BD10="SOF",BF10,0)+IF(BH10="SOF",BJ10,0)+IF(BL10="SOF",BN10,0)+IF(BP10="SOF",BR10,0)+IF(BT10="SOF",BV10,0)+IF(BX10="SOF",BZ10,0)+IF(CB10="SOF",CD10,0)+IF(CF10="SOF",CH10,0)+IF(CJ10="SOF",CL10,0)+IF(CN10="SOF",CP10,0)+IF(CR10="SOF",CT10,0)+IF(CV10="SOF",CX10,0)+IF(CZ10="SOF",DB10,0)+IF(DD10="SOF",DF10,0)+IF(DH10="SOF",DJ10,0)+IF(DL10="SOF",DN10,0)+IF(DP10="SOF",DR10,0)+IF(DT10="SOF",DV10,0)+IF(DX10="SOF",DZ10,0)))+G10&" / "&(IF(H10="SOF",J10,0)+IF(L10="SOF",N10,0)+IF(P10="SOF",R10,0)+IF(T10="SOF",V10,0)+IF(X10="SOF",Z10,0)+IF(AB10="SOF",AD10,0)+IF(AF10="SOF",AH10,0)+IF(AJ10="SOF",AL10,0)+IF(AN10="SOF",AP10,0)+IF(AR10="SOF",AT10,0)+IF(AV10="SOF",AX10,0)+IF(AZ10="SOF",BB10,0)+IF(BD10="SOF",BF10,0)+IF(BH10="SOF",BJ10,0)+IF(BL10="SOF",BN10,0)+IF(BP10="SOF",BR10,0)+IF(BT10="SOF",BV10,0)+IF(BX10="SOF",BZ10,0)+IF(CB10="SOF",CD10,0)+IF(CF10="SOF",CH10,0)+IF(CJ10="SOF",CL10,0)+IF(CN10="SOF",CP10,0)+IF(CR10="SOF",CT10,0)+IF(CV10="SOF",CX10,0)+IF(CZ10="SOF",DB10,0)+IF(DD10="SOF",DF10,0)+IF(DH10="SOF",DJ10,0)+IF(DL10="SOF",DN10,0)+IF(DP10="SOF",DR10,0)+IF(DT10="SOF",DV10,0)+IF(DX10="SOF",DZ10,0))&" / "&SUM(K10,O10,S10,W10,AA10,AE10,AI10,AM10,AQ10,AU10,AY10,BC10,BG10,BK10,BO10,BS10,BW10,CA10,CE10,CI10,CM10,CQ10,CU10,CY10,DC10,DG10,DK10,DO10,DS10,DW10,EA10) -> 56 / 0 / 0 | C10: =(SUM(I10,M10,Q10,U10,Y10,AC10,AG10,AK10,AO10,AS10,AW10,BA10,BE10,BI10,BM10,BQ10,BU10,BY10,CC10,CG10,CK10,CO10,CS10,CW10,DA10,DE10,DI10,DM10,DQ10,DU10,DY10))+F10 -> 1.375 | D10: 0 | E10: 9,33 Tage | AF10: 440oS | AG10: 3:00 | AH10: 3 | AL10: 0 | AP10: 0 | AR10: 434oS | AS10: 10:00 | AT10: 10 | AV10: 436oS-TAF | AW10: 10:00 | AX10: 10 | BB10: 0 | BF10: 0 | BH10: 433oS | BI10: 0.45833333 | BJ10: 11 | BL10: 439oS | BM10: 0.5 | BN10: 12 | BX10: 434oS | BY10: 0.41666667 | BZ10: 10
A11: =IF(ISERROR(Lenker!A5),"N.N.",Lenker!A5) -> Hinteregger, Manfred | B11: =(SUM(J11,N11,R11,V11,Z11,AD11,AH11,AL11,AP11,AT11,AX11,BB11,BF11,BJ11,BN11,BR11,BV11,BZ11,CD11,CH11,CL11,CP11,CT11,CX11,DB11,DF11,DJ11,DN11,DR11,DV11,DZ11)-(IF(H11="SOF",J11,0)+IF(L11="SOF",N11,0)+IF(P11="SOF",R11,0)+IF(T11="SOF",V11,0)+IF(X11="SOF",Z11,0)+IF(AB11="SOF",AD11,0)+IF(AF11="SOF",AH11,0)+IF(AJ11="SOF",AL11,0)+IF(AN11="SOF",AP11,0)+IF(AR11="SOF",AT11,0)+IF(AV11="SOF",AX11,0)+IF(AZ11="SOF",BB11,0)+IF(BD11="SOF",BF11,0)+IF(BH11="SOF",BJ11,0)+IF(BL11="SOF",BN11,0)+IF(BP11="SOF",BR11,0)+IF(BT11="SOF",BV11,0)+IF(BX11="SOF",BZ11,0)+IF(CB11="SOF",CD11,0)+IF(CF11="SOF",CH11,0)+IF(CJ11="SOF",CL11,0)+IF(CN11="SOF",CP11,0)+IF(CR11="SOF",CT11,0)+IF(CV11="SOF",CX11,0)+IF(CZ11="SOF",DB11,0)+IF(DD11="SOF",DF11,0)+IF(DH11="SOF",DJ11,0)+IF(DL11="SOF",DN11,0)+IF(DP11="SOF",DR11,0)+IF(DT11="SOF",DV11,0)+IF(DX11="SOF",DZ11,0)))+G11&" / "&(IF(H11="SOF",J11,0)+IF(L11="SOF",N11,0)+IF(P11="SOF",R11,0)+IF(T11="SOF",V11,0)+IF(X11="SOF",Z11,0)+IF(AB11="SOF",AD11,0)+IF(AF11="SOF",AH11,0)+IF(AJ11="SOF",AL11,0)+IF(AN11="SOF",AP11,0)+IF(AR11="SOF",AT11,0)+IF(AV11="SOF",AX11,0)+IF(AZ11="SOF",BB11,0)+IF(BD11="SOF",BF11,0)+IF(BH11="SOF",BJ11,0)+IF(BL11="SOF",BN11,0)+IF(BP11="SOF",BR11,0)+IF(BT11="SOF",BV11,0)+IF(BX11="SOF",BZ11,0)+IF(CB11="SOF",CD11,0)+IF(CF11="SOF",CH11,0)+IF(CJ11="SOF",CL11,0)+IF(CN11="SOF",CP11,0)+IF(CR11="SOF",CT11,0)+IF(CV11="SOF",CX11,0)+IF(CZ11="SOF",DB11,0)+IF(DD11="SOF",DF11,0)+IF(DH11="SOF",DJ11,0)+IF(DL11="SOF",DN11,0)+IF(DP11="SOF",DR11,0)+IF(DT11="SOF",DV11,0)+IF(DX11="SOF",DZ11,0))&" / "&SUM(K11,O11,S11,W11,AA11,AE11,AI11,AM11,AQ11,AU11,AY11,BC11,BG11,BK11,BO11,BS11,BW11,CA11,CE11,CI11,CM11,CQ11,CU11,CY11,DC11,DG11,DK11,DO11,DS11,DW11,EA11) -> 87 / 0 / 0 | C11: =(SUM(I11,M11,Q11,U11,Y11,AC11,AG11,AK11,AO11,AS11,AW11,BA11,BE11,BI11,BM11,BQ11,BU11,BY11,CC11,CG11,CK11,CO11,CS11,CW11,DA11,DE11,DI11,DM11,DQ11,DU11,DY11))+F11 -> 1.7916667 | D11: 0 | E11: 5 Tage | AF11: 431oS | AG11: 11:00 | AH11: 11 | AJ11: 431oS | AK11: 11:00 | AL11: 11 | AN11: 431oS | AO11: 11:00 | AP11: 11 | AT11: 0 | AV11: 431oS | AW11: 11:00 | AX11: 11 | BB11: 0 | BF11: 0 | BH11: 434oS | BI11: 0.41666667 | BJ11: 10 | BL11: 437oS | BM11: 0.45833333 | BN11: 11 | BT11: 436oS-TAF | BU11: 0.41666667 | BV11: 10 | BX11: 439oS | BY11: 0.5 | BZ11: 12
A12: =IF(ISERROR(Lenker!A6),"N.N.",Lenker!A6) -> Kandolf, Alfred | B12: =(SUM(J12,N12,R12,V12,Z12,AD12,AH12,AL12,AP12,AT12,AX12,BB12,BF12,BJ12,BN12,BR12,BV12,BZ12,CD12,CH12,CL12,CP12,CT12,CX12,DB12,DF12,DJ12,DN12,DR12,DV12,DZ12)-(IF(H12="SOF",J12,0)+IF(L12="SOF",N12,0)+IF(P12="SOF",R12,0)+IF(T12="SOF",V12,0)+IF(X12="SOF",Z12,0)+IF(AB12="SOF",AD12,0)+IF(AF12="SOF",AH12,0)+IF(AJ12="SOF",AL12,0)+IF(AN12="SOF",AP12,0)+IF(AR12="SOF",AT12,0)+IF(AV12="SOF",AX12,0)+IF(AZ12="SOF",BB12,0)+IF(BD12="SOF",BF12,0)+IF(BH12="SOF",BJ12,0)+IF(BL12="SOF",BN12,0)+IF(BP12="SOF",BR12,0)+IF(BT12="SOF",BV12,0)+IF(BX12="SOF",BZ12,0)+IF(CB12="SOF",CD12,0)+IF(CF12="SOF",CH12,0)+IF(CJ12="SOF",CL12,0)+IF(CN12="SOF",CP12,0)+IF(CR12="SOF",CT12,0)+IF(CV12="SOF",CX12,0)+IF(CZ12="SOF",DB12,0)+IF(DD12="SOF",DF12,0)+IF(DH12="SOF",DJ12,0)+IF(DL12="SOF",DN12,0)+IF(DP12="SOF",DR12,0)+IF(DT12="SOF",DV12,0)+IF(DX12="SOF",DZ12,0)))+G12&" / "&(IF(H12="SOF",J12,0)+IF(L12="SOF",N12,0)+IF(P12="SOF",R12,0)+IF(T12="SOF",V12,0)+IF(X12="SOF",Z12,0)+IF(AB12="SOF",AD12,0)+IF(AF12="SOF",AH12,0)+IF(AJ12="SOF",AL12,0)+IF(AN12="SOF",AP12,0)+IF(AR12="SOF",AT12,0)+IF(AV12="SOF",AX12,0)+IF(AZ12="SOF",BB12,0)+IF(BD12="SOF",BF12,0)+IF(BH12="SOF",BJ12,0)+IF(BL12="SOF",BN12,0)+IF(BP12="SOF",BR12,0)+IF(BT12="SOF",BV12,0)+IF(BX12="SOF",BZ12,0)+IF(CB12="SOF",CD12,0)+IF(CF12="SOF",CH12,0)+IF(CJ12="SOF",CL12,0)+IF(CN12="SOF",CP12,0)+IF(CR12="SOF",CT12,0)+IF(CV12="SOF",CX12,0)+IF(CZ12="SOF",DB12,0)+IF(DD12="SOF",DF12,0)+IF(DH12="SOF",DJ12,0)+IF(DL12="SOF",DN12,0)+IF(DP12="SOF",DR12,0)+IF(DT12="SOF",DV12,0)+IF(DX12="SOF",DZ12,0))&" / "&SUM(K12,O12,S12,W12,AA12,AE12,AI12,AM12,AQ12,AU12,AY12,BC12,BG12,BK12,BO12,BS12,BW12,CA12,CE12,CI12,CM12,CQ12,CU12,CY12,DC12,DG12,DK12,DO12,DS12,DW12,EA12) -> 67 / 0 / 0 | C12: =(SUM(I12,M12,Q12,U12,Y12,AC12,AG12,AK12,AO12,AS12,AW12,BA12,BE12,BI12,BM12,BQ12,BU12,BY12,CC12,CG12,CK12,CO12,CS12,CW12,DA12,DE12,DI12,DM12,DQ12,DU12,DY12))+F12 -> 1.4166667 | D12: 0 | E12: 23 Tage | AF12: 434oS | AG12: 10:00 | AH12: 10 | AJ12: 434oS | AK12: 10:00 | AL12: 10 | AN12: 434oS | AO12: 10:00 | AP12: 10 | AR12: 440oS | AS12: 3:00 | AT12: 3 | AX12: 0 | BB12: 0 | BF12: 0 | BH12: 435oS-HOF | BI12: 0.5 | BJ12: 12 | BP12: 436oS-TAF | BQ12: 0.41666667 | BR12: 10 | BT12: 439oS | BU12: 0.5 | BV12: 12
A13: =IF(ISERROR(Lenker!A7),"N.N.",Lenker!A7) -> Konheiser, Elisabeth | B13: =(SUM(J13,N13,R13,V13,Z13,AD13,AH13,AL13,AP13,AT13,AX13,BB13,BF13,BJ13,BN13,BR13,BV13,BZ13,CD13,CH13,CL13,CP13,CT13,CX13,DB13,DF13,DJ13,DN13,DR13,DV13,DZ13)-(IF(H13="SOF",J13,0)+IF(L13="SOF",N13,0)+IF(P13="SOF",R13,0)+IF(T13="SOF",V13,0)+IF(X13="SOF",Z13,0)+IF(AB13="SOF",AD13,0)+IF(AF13="SOF",AH13,0)+IF(AJ13="SOF",AL13,0)+IF(AN13="SOF",AP13,0)+IF(AR13="SOF",AT13,0)+IF(AV13="SOF",AX13,0)+IF(AZ13="SOF",BB13,0)+IF(BD13="SOF",BF13,0)+IF(BH13="SOF",BJ13,0)+IF(BL13="SOF",BN13,0)+IF(BP13="SOF",BR13,0)+IF(BT13="SOF",BV13,0)+IF(BX13="SOF",BZ13,0)+IF(CB13="SOF",CD13,0)+IF(CF13="SOF",CH13,0)+IF(CJ13="SOF",CL13,0)+IF(CN13="SOF",CP13,0)+IF(CR13="SOF",CT13,0)+IF(CV13="SOF",CX13,0)+IF(CZ13="SOF",DB13,0)+IF(DD13="SOF",DF13,0)+IF(DH13="SOF",DJ13,0)+IF(DL13="SOF",DN13,0)+IF(DP13="SOF",DR13,0)+IF(DT13="SOF",DV13,0)+IF(DX13="SOF",DZ13,0)))+G13&" / "&(IF(H13="SOF",J13,0)+IF(L13="SOF",N13,0)+IF(P13="SOF",R13,0)+IF(T13="SOF",V13,0)+IF(X13="SOF",Z13,0)+IF(AB13="SOF",AD13,0)+IF(AF13="SOF",AH13,0)+IF(AJ13="SOF",AL13,0)+IF(AN13="SOF",AP13,0)+IF(AR13="SOF",AT13,0)+IF(AV13="SOF",AX13,0)+IF(AZ13="SOF",BB13,0)+IF(BD13="SOF",BF13,0)+IF(BH13="SOF",BJ13,0)+IF(BL13="SOF",BN13,0)+IF(BP13="SOF",BR13,0)+IF(BT13="SOF",BV13,0)+IF(BX13="SOF",BZ13,0)+IF(CB13="SOF",CD13,0)+IF(CF13="SOF",CH13,0)+IF(CJ13="SOF",CL13,0)+IF(CN13="SOF",CP13,0)+IF(CR13="SOF",CT13,0)+IF(CV13="SOF",CX13,0)+IF(CZ13="SOF",DB13,0)+IF(DD13="SOF",DF13,0)+IF(DH13="SOF",DJ13,0)+IF(DL13="SOF",DN13,0)+IF(DP13="SOF",DR13,0)+IF(DT13="SOF",DV13,0)+IF(DX13="SOF",DZ13,0))&" / "&SUM(K13,O13,S13,W13,AA13,AE13,AI13,AM13,AQ13,AU13,AY13,BC13,BG13,BK13,BO13,BS13,BW13,CA13,CE13,CI13,CM13,CQ13,CU13,CY13,DC13,DG13,DK13,DO13,DS13,DW13,EA13) -> 52 / 0 / 0 | C13: =(SUM(I13,M13,Q13,U13,Y13,AC13,AG13,AK13,AO13,AS13,AW13,BA13,BE13,BI13,BM13,BQ13,BU13,BY13,CC13,CG13,CK13,CO13,CS13,CW13,DA13,DE13,DI13,DM13,DQ13,DU13,DY13))+F13 -> 1.4958333 | D13: 0 | E13: 15,9 Tage | F13: 0.0375 | AH13: 0 | AL13: 0 | AN13: 440oS | AO13: 3:00 | AP13: 3 | AR13: 431oS | AS13: 11:00 | AT13: 11 | AV13: 440oS | AW13: 3:00 | AX13: 3 | BB13: 0 | BF13: 0 | BL13: 435oS-HOF | BM13: 0.5 | BN13: 12 | BP13: 439oS | BQ13: 0.5 | BR13: 12 | BX13: 431oS | BY13: 0.45833333 | BZ13: 11
A14: =IF(ISERROR(Lenker!A8),"N.N.",Lenker!A8) -> Lauhart, Egon | B14: =(SUM(J14,N14,R14,V14,Z14,AD14,AH14,AL14,AP14,AT14,AX14,BB14,BF14,BJ14,BN14,BR14,BV14,BZ14,CD14,CH14,CL14,CP14,CT14,CX14,DB14,DF14,DJ14,DN14,DR14,DV14,DZ14)-(IF(H14="SOF",J14,0)+IF(L14="SOF",N14,0)+IF(P14="SOF",R14,0)+IF(T14="SOF",V14,0)+IF(X14="SOF",Z14,0)+IF(AB14="SOF",AD14,0)+IF(AF14="SOF",AH14,0)+IF(AJ14="SOF",AL14,0)+IF(AN14="SOF",AP14,0)+IF(AR14="SOF",AT14,0)+IF(AV14="SOF",AX14,0)+IF(AZ14="SOF",BB14,0)+IF(BD14="SOF",BF14,0)+IF(BH14="SOF",BJ14,0)+IF(BL14="SOF",BN14,0)+IF(BP14="SOF",BR14,0)+IF(BT14="SOF",BV14,0)+IF(BX14="SOF",BZ14,0)+IF(CB14="SOF",CD14,0)+IF(CF14="SOF",CH14,0)+IF(CJ14="SOF",CL14,0)+IF(CN14="SOF",CP14,0)+IF(CR14="SOF",CT14,0)+IF(CV14="SOF",CX14,0)+IF(CZ14="SOF",DB14,0)+IF(DD14="SOF",DF14,0)+IF(DH14="SOF",DJ14,0)+IF(DL14="SOF",DN14,0)+IF(DP14="SOF",DR14,0)+IF(DT14="SOF",DV14,0)+IF(DX14="SOF",DZ14,0)))+G14&" / "&(IF(H14="SOF",J14,0)+IF(L14="SOF",N14,0)+IF(P14="SOF",R14,0)+IF(T14="SOF",V14,0)+IF(X14="SOF",Z14,0)+IF(AB14="SOF",AD14,0)+IF(AF14="SOF",AH14,0)+IF(AJ14="SOF",AL14,0)+IF(AN14="SOF",AP14,0)+IF(AR14="SOF",AT14,0)+IF(AV14="SOF",AX14,0)+IF(AZ14="SOF",BB14,0)+IF(BD14="SOF",BF14,0)+IF(BH14="SOF",BJ14,0)+IF(BL14="SOF",BN14,0)+IF(BP14="SOF",BR14,0)+IF(BT14="SOF",BV14,0)+IF(BX14="SOF",BZ14,0)+IF(CB14="SOF",CD14,0)+IF(CF14="SOF",CH14,0)+IF(CJ14="SOF",CL14,0)+IF(CN14="SOF",CP14,0)+IF(CR14="SOF",CT14,0)+IF(CV14="SOF",CX14,0)+IF(CZ14="SOF",DB14,0)+IF(DD14="SOF",DF14,0)+IF(DH14="SOF",DJ14,0)+IF(DL14="SOF",DN14,0)+IF(DP14="SOF",DR14,0)+IF(DT14="SOF",DV14,0)+IF(DX14="SOF",DZ14,0))&" / "&SUM(K14,O14,S14,W14,AA14,AE14,AI14,AM14,AQ14,AU14,AY14,BC14,BG14,BK14,BO14,BS14,BW14,CA14,CE14,CI14,CM14,CQ14,CU14,CY14,DC14,DG14,DK14,DO14,DS14,DW14,EA14) -> 66 / 0 / 0 | C14: =(SUM(I14,M14,Q14,U14,Y14,AC14,AG14,AK14,AO14,AS14,AW14,BA14,BE14,BI14,BM14,BQ14,BU14,BY14,CC14,CG14,CK14,CO14,CS14,CW14,DA14,DE14,DI14,DM14,DQ14,DU14,DY14))+F14 -> 1.8333333 | D14: 0 | E14: 8,92 Tage | AH14: 0 | AJ14: 436oS-TAF | AK14: 10:00 | AL14: 10 | AP14: 0 | AR14: 432oS | AS14: 12:00 | AT14: 12 | AX14: 0 | BB14: 0 | BF14: 0 | BH14: 436oS-TAF | BI14: 0.41666667 | BJ14: 10 | BL14: 438oS | BM14: 0.45833333 | BN14: 11 | BT14: 437oS | BU14: 0.45833333 | BV14: 11 | BX14: 435oS-HOF | BY14: 0.5 | BZ14: 12
A15: =IF(ISERROR(Lenker!A9),"N.N.",Lenker!A9) -> Madrutter, Anton | B15: =(SUM(J15,N15,R15,V15,Z15,AD15,AH15,AL15,AP15,AT15,AX15,BB15,BF15,BJ15,BN15,BR15,BV15,BZ15,CD15,CH15,CL15,CP15,CT15,CX15,DB15,DF15,DJ15,DN15,DR15,DV15,DZ15)-(IF(H15="SOF",J15,0)+IF(L15="SOF",N15,0)+IF(P15="SOF",R15,0)+IF(T15="SOF",V15,0)+IF(X15="SOF",Z15,0)+IF(AB15="SOF",AD15,0)+IF(AF15="SOF",AH15,0)+IF(AJ15="SOF",AL15,0)+IF(AN15="SOF",AP15,0)+IF(AR15="SOF",AT15,0)+IF(AV15="SOF",AX15,0)+IF(AZ15="SOF",BB15,0)+IF(BD15="SOF",BF15,0)+IF(BH15="SOF",BJ15,0)+IF(BL15="SOF",BN15,0)+IF(BP15="SOF",BR15,0)+IF(BT15="SOF",BV15,0)+IF(BX15="SOF",BZ15,0)+IF(CB15="SOF",CD15,0)+IF(CF15="SOF",CH15,0)+IF(CJ15="SOF",CL15,0)+IF(CN15="SOF",CP15,0)+IF(CR15="SOF",CT15,0)+IF(CV15="SOF",CX15,0)+IF(CZ15="SOF",DB15,0)+IF(DD15="SOF",DF15,0)+IF(DH15="SOF",DJ15,0)+IF(DL15="SOF",DN15,0)+IF(DP15="SOF",DR15,0)+IF(DT15="SOF",DV15,0)+IF(DX15="SOF",DZ15,0)))+G15&" / "&(IF(H15="SOF",J15,0)+IF(L15="SOF",N15,0)+IF(P15="SOF",R15,0)+IF(T15="SOF",V15,0)+IF(X15="SOF",Z15,0)+IF(AB15="SOF",AD15,0)+IF(AF15="SOF",AH15,0)+IF(AJ15="SOF",AL15,0)+IF(AN15="SOF",AP15,0)+IF(AR15="SOF",AT15,0)+IF(AV15="SOF",AX15,0)+IF(AZ15="SOF",BB15,0)+IF(BD15="SOF",BF15,0)+IF(BH15="SOF",BJ15,0)+IF(BL15="SOF",BN15,0)+IF(BP15="SOF",BR15,0)+IF(BT15="SOF",BV15,0)+IF(BX15="SOF",BZ15,0)+IF(CB15="SOF",CD15,0)+IF(CF15="SOF",CH15,0)+IF(CJ15="SOF",CL15,0)+IF(CN15="SOF",CP15,0)+IF(CR15="SOF",CT15,0)+IF(CV15="SOF",CX15,0)+IF(CZ15="SOF",DB15,0)+IF(DD15="SOF",DF15,0)+IF(DH15="SOF",DJ15,0)+IF(DL15="SOF",DN15,0)+IF(DP15="SOF",DR15,0)+IF(DT15="SOF",DV15,0)+IF(DX15="SOF",DZ15,0))&" / "&SUM(K15,O15,S15,W15,AA15,AE15,AI15,AM15,AQ15,AU15,AY15,BC15,BG15,BK15,BO15,BS15,BW15,CA15,CE15,CI15,CM15,CQ15,CU15,CY15,DC15,DG15,DK15,DO15,DS15,DW15,EA15) -> 82 / 0 / 0 | C15: =(SUM(I15,M15,Q15,U15,Y15,AC15,AG15,AK15,AO15,AS15,AW15,BA15,BE15,BI15,BM15,BQ15,BU15,BY15,CC15,CG15,CK15,CO15,CS15,CW15,DA15,DE15,DI15,DM15,DQ15,DU15,DY15))+F15-C39 -> 0.375 | D15: 0 | E15: 28 Tage | AF15: 435oS-HOF | AG15: 12:00 | AH15: 12 | AJ15: 435oS-HOF | AK15: 12:00 | AL15: 12 | AN15: 435oS-HOF | AO15: 12:00 | AP15: 12 | AT15: 0 | AV15: 434oS | AW15: 10:00 | AX15: 10 | BB15: 0 | BF15: 0 | BH15: 431oS | BI15: 0.45833333 | BJ15: 11 | BL15: 431oS | BM15: 0.45833333 | BN15: 11 | BP15: 431oS | BQ15: 0.45833333 | BR15: 11 | BT15: 440oS | BU15: 0.125 | BV15: 3
A16: =IF(ISERROR(Lenker!A10),"N.N.",Lenker!A10) -> Niederbichler, Daniel | B16: =(SUM(J16,N16,R16,V16,Z16,AD16,AH16,AL16,AP16,AT16,AX16,BB16,BF16,BJ16,BN16,BR16,BV16,BZ16,CD16,CH16,CL16,CP16,CT16,CX16,DB16,DF16,DJ16,DN16,DR16,DV16,DZ16)-(IF(H16="SOF",J16,0)+IF(L16="SOF",N16,0)+IF(P16="SOF",R16,0)+IF(T16="SOF",V16,0)+IF(X16="SOF",Z16,0)+IF(AB16="SOF",AD16,0)+IF(AF16="SOF",AH16,0)+IF(AJ16="SOF",AL16,0)+IF(AN16="SOF",AP16,0)+IF(AR16="SOF",AT16,0)+IF(AV16="SOF",AX16,0)+IF(AZ16="SOF",BB16,0)+IF(BD16="SOF",BF16,0)+IF(BH16="SOF",BJ16,0)+IF(BL16="SOF",BN16,0)+IF(BP16="SOF",BR16,0)+IF(BT16="SOF",BV16,0)+IF(BX16="SOF",BZ16,0)+IF(CB16="SOF",CD16,0)+IF(CF16="SOF",CH16,0)+IF(CJ16="SOF",CL16,0)+IF(CN16="SOF",CP16,0)+IF(CR16="SOF",CT16,0)+IF(CV16="SOF",CX16,0)+IF(CZ16="SOF",DB16,0)+IF(DD16="SOF",DF16,0)+IF(DH16="SOF",DJ16,0)+IF(DL16="SOF",DN16,0)+IF(DP16="SOF",DR16,0)+IF(DT16="SOF",DV16,0)+IF(DX16="SOF",DZ16,0)))+G16&" / "&(IF(H16="SOF",J16,0)+IF(L16="SOF",N16,0)+IF(P16="SOF",R16,0)+IF(T16="SOF",V16,0)+IF(X16="SOF",Z16,0)+IF(AB16="SOF",AD16,0)+IF(AF16="SOF",AH16,0)+IF(AJ16="SOF",AL16,0)+IF(AN16="SOF",AP16,0)+IF(AR16="SOF",AT16,0)+IF(AV16="SOF",AX16,0)+IF(AZ16="SOF",BB16,0)+IF(BD16="SOF",BF16,0)+IF(BH16="SOF",BJ16,0)+IF(BL16="SOF",BN16,0)+IF(BP16="SOF",BR16,0)+IF(BT16="SOF",BV16,0)+IF(BX16="SOF",BZ16,0)+IF(CB16="SOF",CD16,0)+IF(CF16="SOF",CH16,0)+IF(CJ16="SOF",CL16,0)+IF(CN16="SOF",CP16,0)+IF(CR16="SOF",CT16,0)+IF(CV16="SOF",CX16,0)+IF(CZ16="SOF",DB16,0)+IF(DD16="SOF",DF16,0)+IF(DH16="SOF",DJ16,0)+IF(DL16="SOF",DN16,0)+IF(DP16="SOF",DR16,0)+IF(DT16="SOF",DV16,0)+IF(DX16="SOF",DZ16,0))&" / "&SUM(K16,O16,S16,W16,AA16,AE16,AI16,AM16,AQ16,AU16,AY16,BC16,BG16,BK16,BO16,BS16,BW16,CA16,CE16,CI16,CM16,CQ16,CU16,CY16,DC16,DG16,DK16,DO16,DS16,DW16,EA16) -> 80 / 0 / 0 | C16: =(SUM(I16,M16,Q16,U16,Y16,AC16,AG16,AK16,AO16,AS16,AW16,BA16,BE16,BI16,BM16,BQ16,BU16,BY16,CC16,CG16,CK16,CO16,CS16,CW16,DA16,DE16,DI16,DM16,DQ16,DU16,DY16))+F16 -> 1.5 | D16: 0 | E16: 18 Tage | AF16: 433oS | AG16: 11:00 | AH16: 11 | AJ16: 433oS | AK16: 11:00 | AL16: 11 | AN16: 433oS | AO16: 11:00 | AP16: 11 | AT16: 0 | AV16: 433oS | AW16: 11:00 | AX16: 11 | BB16: 0 | BF16: 0 | BH16: 437oS | BI16: 0.45833333 | BJ16: 11 | BL16: 440oS | BM16: 0.125 | BN16: 3 | BT16: 431oS | BU16: 0.45833333 | BV16: 11 | BX16: 438oS | BY16: 0.45833333 | BZ16: 11
A17: =IF(ISERROR(Lenker!A11),"N.N.",Lenker!A11) -> Nurikic, Ervin | B17: =(SUM(J17,N17,R17,V17,Z17,AD17,AH17,AL17,AP17,AT17,AX17,BB17,BF17,BJ17,BN17,BR17,BV17,BZ17,CD17,CH17,CL17,CP17,CT17,CX17,DB17,DF17,DJ17,DN17,DR17,DV17,DZ17)-(IF(H17="SOF",J17,0)+IF(L17="SOF",N17,0)+IF(P17="SOF",R17,0)+IF(T17="SOF",V17,0)+IF(X17="SOF",Z17,0)+IF(AB17="SOF",AD17,0)+IF(AF17="SOF",AH17,0)+IF(AJ17="SOF",AL17,0)+IF(AN17="SOF",AP17,0)+IF(AR17="SOF",AT17,0)+IF(AV17="SOF",AX17,0)+IF(AZ17="SOF",BB17,0)+IF(BD17="SOF",BF17,0)+IF(BH17="SOF",BJ17,0)+IF(BL17="SOF",BN17,0)+IF(BP17="SOF",BR17,0)+IF(BT17="SOF",BV17,0)+IF(BX17="SOF",BZ17,0)+IF(CB17="SOF",CD17,0)+IF(CF17="SOF",CH17,0)+IF(CJ17="SOF",CL17,0)+IF(CN17="SOF",CP17,0)+IF(CR17="SOF",CT17,0)+IF(CV17="SOF",CX17,0)+IF(CZ17="SOF",DB17,0)+IF(DD17="SOF",DF17,0)+IF(DH17="SOF",DJ17,0)+IF(DL17="SOF",DN17,0)+IF(DP17="SOF",DR17,0)+IF(DT17="SOF",DV17,0)+IF(DX17="SOF",DZ17,0)))+G17&" / "&(IF(H17="SOF",J17,0)+IF(L17="SOF",N17,0)+IF(P17="SOF",R17,0)+IF(T17="SOF",V17,0)+IF(X17="SOF",Z17,0)+IF(AB17="SOF",AD17,0)+IF(AF17="SOF",AH17,0)+IF(AJ17="SOF",AL17,0)+IF(AN17="SOF",AP17,0)+IF(AR17="SOF",AT17,0)+IF(AV17="SOF",AX17,0)+IF(AZ17="SOF",BB17,0)+IF(BD17="SOF",BF17,0)+IF(BH17="SOF",BJ17,0)+IF(BL17="SOF",BN17,0)+IF(BP17="SOF",BR17,0)+IF(BT17="SOF",BV17,0)+IF(BX17="SOF",BZ17,0)+IF(CB17="SOF",CD17,0)+IF(CF17="SOF",CH17,0)+IF(CJ17="SOF",CL17,0)+IF(CN17="SOF",CP17,0)+IF(CR17="SOF",CT17,0)+IF(CV17="SOF",CX17,0)+IF(CZ17="SOF",DB17,0)+IF(DD17="SOF",DF17,0)+IF(DH17="SOF",DJ17,0)+IF(DL17="SOF",DN17,0)+IF(DP17="SOF",DR17,0)+IF(DT17="SOF",DV17,0)+IF(DX17="SOF",DZ17,0))&" / "&SUM(K17,O17,S17,W17,AA17,AE17,AI17,AM17,AQ17,AU17,AY17,BC17,BG17,BK17,BO17,BS17,BW17,CA17,CE17,CI17,CM17,CQ17,CU17,CY17,DC17,DG17,DK17,DO17,DS17,DW17,EA17) -> 60 / 0 / 0 | C17: =(SUM(I17,M17,Q17,U17,Y17,AC17,AG17,AK17,AO17,AS17,AW17,BA17,BE17,BI17,BM17,BQ17,BU17,BY17,CC17,CG17,CK17,CO17,CS17,CW17,DA17,DE17,DI17,DM17,DQ17,DU17,DY17))+F17 -> 1.4166667 | D17: 0 | E17: 9 Tage | AH17: 0 | AJ17: 440oS | AK17: 3:00 | AL17: 3 | AP17: 0 | AR17: 437oS | AS17: 11:00 | AT17: 11 | AV17: 435oS-HOF | AW17: 12:00 | AX17: 12 | BB17: 0 | BF17: 0 | BH17: 438oS | BI17: 0.45833333 | BJ17: 11 | BP17: 433oS | BQ17: 0.45833333 | BR17: 11 | BT17: 432oS | BU17: 0.5 | BV17: 12
A18: =IF(ISERROR(Lenker!A12),"N.N.",Lenker!A12) -> Obersteiner, Roland | B18: =(SUM(J18,N18,R18,V18,Z18,AD18,AH18,AL18,AP18,AT18,AX18,BB18,BF18,BJ18,BN18,BR18,BV18,BZ18,CD18,CH18,CL18,CP18,CT18,CX18,DB18,DF18,DJ18,DN18,DR18,DV18,DZ18)-(IF(H18="SOF",J18,0)+IF(L18="SOF",N18,0)+IF(P18="SOF",R18,0)+IF(T18="SOF",V18,0)+IF(X18="SOF",Z18,0)+IF(AB18="SOF",AD18,0)+IF(AF18="SOF",AH18,0)+IF(AJ18="SOF",AL18,0)+IF(AN18="SOF",AP18,0)+IF(AR18="SOF",AT18,0)+IF(AV18="SOF",AX18,0)+IF(AZ18="SOF",BB18,0)+IF(BD18="SOF",BF18,0)+IF(BH18="SOF",BJ18,0)+IF(BL18="SOF",BN18,0)+IF(BP18="SOF",BR18,0)+IF(BT18="SOF",BV18,0)+IF(BX18="SOF",BZ18,0)+IF(CB18="SOF",CD18,0)+IF(CF18="SOF",CH18,0)+IF(CJ18="SOF",CL18,0)+IF(CN18="SOF",CP18,0)+IF(CR18="SOF",CT18,0)+IF(CV18="SOF",CX18,0)+IF(CZ18="SOF",DB18,0)+IF(DD18="SOF",DF18,0)+IF(DH18="SOF",DJ18,0)+IF(DL18="SOF",DN18,0)+IF(DP18="SOF",DR18,0)+IF(DT18="SOF",DV18,0)+IF(DX18="SOF",DZ18,0)))+G18&" / "&(IF(H18="SOF",J18,0)+IF(L18="SOF",N18,0)+IF(P18="SOF",R18,0)+IF(T18="SOF",V18,0)+IF(X18="SOF",Z18,0)+IF(AB18="SOF",AD18,0)+IF(AF18="SOF",AH18,0)+IF(AJ18="SOF",AL18,0)+IF(AN18="SOF",AP18,0)+IF(AR18="SOF",AT18,0)+IF(AV18="SOF",AX18,0)+IF(AZ18="SOF",BB18,0)+IF(BD18="SOF",BF18,0)+IF(BH18="SOF",BJ18,0)+IF(BL18="SOF",BN18,0)+IF(BP18="SOF",BR18,0)+IF(BT18="SOF",BV18,0)+IF(BX18="SOF",BZ18,0)+IF(CB18="SOF",CD18,0)+IF(CF18="SOF",CH18,0)+IF(CJ18="SOF",CL18,0)+IF(CN18="SOF",CP18,0)+IF(CR18="SOF",CT18,0)+IF(CV18="SOF",CX18,0)+IF(CZ18="SOF",DB18,0)+IF(DD18="SOF",DF18,0)+IF(DH18="SOF",DJ18,0)+IF(DL18="SOF",DN18,0)+IF(DP18="SOF",DR18,0)+IF(DT18="SOF",DV18,0)+IF(DX18="SOF",DZ18,0))&" / "&SUM(K18,O18,S18,W18,AA18,AE18,AI18,AM18,AQ18,AU18,AY18,BC18,BG18,BK18,BO18,BS18,BW18,CA18,CE18,CI18,CM18,CQ18,CU18,CY18,DC18,DG18,DK18,DO18,DS18,DW18,EA18) -> 54 / 0 / 0 | C18: =(SUM(I18,M18,Q18,U18,Y18,AC18,AG18,AK18,AO18,AS18,AW18,BA18,BE18,BI18,BM18,BQ18,BU18,BY18,CC18,CG18,CK18,CO18,CS18,CW18,DA18,DE18,DI18,DM18,DQ18,DU18,DY18))+F18 -> 1.375 | D18: 0 | E18: 4,36 Tage | AH18: 0 | AL18: 0 | AN18: 436oS-TAF | AO18: 10:00 | AP18: 10 | AR18: 438oS | AS18: 11:00 | AT18: 11 | AX18: 0 | BB18: 0 | BF18: 0 | BH18: 439oS | BI18: 0.5 | BJ18: 12 | BP18: 437oS | BQ18: 0.45833333 | BR18: 11 | BX18: 436oS-TAF | BY18: 0.41666667 | BZ18: 10
